
# Created by Ruins mod version 16.7 Ingame Parser
# authoring Player: lafuller

weight=1
embed_into_distance=39
acceptable_target_blocks=
unacceptable_target_blocks=flowing_lava,lava,ice,bedrock,netherrack,nether_brick,nether_brick_fence,soul_sand,quartz_ore,end_stone,obsidian,iron_bars,cloud,flesh,ash_block,slime_grass,slime_congealed,slime_dirt
dimensions=36,17,17
allowable_overhang=0
max_leveling=39
leveling_buffer=-1
preserve_water=0
preserve_lava=0

adjoining_template=Gilly/GillyCatacomb1;6;70;-14;100
adjoining_template=Gilly/GillyCatacomb1;12;70;-28;100
adjoining_template=Gilly/GillyCatacomb1;20;70;-8;100
adjoining_template=Gilly/GillyCatacomb1;26;70;-22;100

adjoining_template=Gilly/GillyCatacomb1;-14;70;-6;100
adjoining_template=Gilly/GillyCatacomb1;-20;70;8;100
adjoining_template=Gilly/GillyCatacomb1;-28;70;-12;100
adjoining_template=Gilly/GillyCatacomb1;-34;70;2;100

adjoining_template=Gilly/GillyCatacomb1;-8;70;-20;100
adjoining_template=Gilly/GillyCatacomb1;-22;70;-26;100
adjoining_template=Gilly/GillyCatacomb1;-2;70;-34;100
adjoining_template=Gilly/GillyCatacomb1;-16;70;-40;100

adjoining_template=Gilly/GillyCatacomb1;14;70;6;100
adjoining_template=Gilly/GillyCatacomb1;-6;70;14;100
adjoining_template=Gilly/GillyCatacomb1;8;70;20;100

rule1=0,100,preserveBlock
rule2=0,100,stonebrick-0,stonebrick-1,stonebrick-2,stone-5,stone-5,stone-6,stone-6,cobblestone
rule3=0,100,stonebrick-0,stonebrick-0,stonebrick-1,stonebrick-1,stonebrick-2,stonebrick-2,stone-5,cobblestone
rule4=0,100,minecraft:stone_brick_stairs-3
rule5=0,100,minecraft:stone_brick_stairs-1
rule6=0,100,minecraft:stone_brick_stairs-2
rule7=0,100,minecraft:stone_brick_stairs-0
rule8=0,100,minecraft:cobblestone_wall-0
rule9=0,100,minecraft:stone_brick_stairs-7
rule10=0,100,minecraft:stone_brick_stairs-5
rule11=0,100,minecraft:stone_brick_stairs-4
rule12=0,100,minecraft:stone_brick_stairs-6
rule13=0,100,minecraft:stone_slab-13
rule14=0,100,sponge-0,diamond_ore-0,lapis_block-0,gold_block-0,emerald_block-0,iron_block-0,coal_block-0,gold_ore-0,redstone_ore-0,lapis_ore-0,emerald_ore-0,lapis_block-0,gold_block-0,gold_ore-0,redstone_ore-0,lapis_ore-0,emerald_ore-0
rule15=0,100,minecraft:sea_lantern-0
rule16=1,100,minecraft:torch-5
rule17=0,100,ChestGenHook:chests/simple_dungeon:5-3

layer
1,1,3,3,3,3,3,2,2,2,1,1,1,1,1,1,1
1,1,3,3,3,3,3,2,2,2,2,2,2,1,1,1,1
1,1,3,3,3,3,3,2,2,2,2,2,2,3,3,3,3
1,1,3,3,3,2,2,2,2,2,2,2,2,3,3,3,3
1,2,2,2,2,2,2,2,2,2,2,2,2,3,3,3,3
1,2,2,2,2,2,2,2,2,2,2,2,2,2,3,3,3
1,2,2,2,2,2,2,2,2,2,2,2,2,2,3,3,3
2,2,2,2,2,2,2,6,5,4,2,2,2,2,2,2,2
2,2,2,2,2,2,2,6,0,4,2,2,2,2,2,2,2
2,2,2,2,2,2,2,6,7,4,2,2,2,2,2,2,2
3,3,3,2,2,2,2,2,2,2,2,2,2,2,2,2,1
3,3,3,2,2,2,2,2,2,2,2,2,2,2,2,2,1
3,3,3,3,2,2,2,2,2,2,2,2,2,2,2,2,1
3,3,3,3,2,2,2,2,2,2,2,2,3,3,3,1,1
3,3,3,3,2,2,2,2,2,2,3,3,3,3,3,1,1
1,1,1,1,2,2,2,2,2,2,3,3,3,3,3,1,1
1,1,1,1,1,1,1,2,2,2,3,3,3,3,3,1,1
endlayer

layer
1,1,3,3,3,3,3,0,0,0,1,1,1,1,1,1,1
1,1,3,3,3,3,6,0,0,0,0,0,0,1,1,1,1
1,1,3,3,3,3,5,0,0,0,0,0,0,3,3,3,3
1,1,3,3,3,0,0,0,0,0,0,0,0,3,3,3,3
1,0,0,0,0,0,0,0,0,0,0,0,0,3,3,3,3
1,0,0,0,0,0,0,0,0,0,0,0,0,0,3,3,3
1,0,0,0,0,0,0,0,0,0,0,0,0,0,4,5,3
0,0,0,0,0,0,0,0,0,0,0,0,0,0,0,0,0
0,0,0,0,0,0,0,0,0,0,0,0,0,0,0,0,0
0,0,0,0,0,0,0,0,0,0,0,0,0,0,0,0,0
3,7,6,0,0,0,0,0,0,0,0,0,0,0,0,0,1
3,3,3,0,0,0,0,0,0,0,0,0,0,0,0,0,1
3,3,3,3,0,0,0,0,0,0,0,0,0,0,0,0,1
3,3,3,3,0,0,0,0,0,0,0,0,3,3,3,1,1
3,3,3,3,0,0,0,0,0,0,7,3,3,3,3,1,1
1,1,1,1,0,0,0,0,0,0,4,3,3,3,3,1,1
1,1,1,1,1,1,1,0,0,0,3,3,3,3,3,1,1
endlayer

layer
1,1,3,3,3,3,3,0,0,0,1,1,1,1,1,1,1
1,1,3,3,3,6,0,0,0,0,0,0,0,1,1,1,1
1,1,3,3,3,6,0,0,0,0,0,0,0,3,3,3,3
1,1,3,3,3,0,0,0,0,0,0,0,0,3,3,3,3
1,0,0,0,0,0,0,0,0,0,0,0,0,3,3,3,3
1,0,0,0,0,0,0,0,0,0,0,0,0,0,5,5,3
1,0,0,0,0,0,0,0,0,0,0,0,0,0,0,0,3
0,0,0,0,0,0,0,0,0,0,0,0,0,0,0,0,0
0,0,0,0,0,0,0,0,0,0,0,0,0,0,0,0,0
0,0,0,0,0,0,0,0,0,0,0,0,0,0,0,0,0
3,0,0,0,0,0,0,0,0,0,0,0,0,0,0,0,1
3,7,7,0,0,0,0,0,0,0,0,0,0,0,0,0,1
3,3,3,3,0,0,0,0,0,0,0,0,0,0,0,0,1
3,3,3,3,0,0,0,0,0,0,0,0,3,3,3,1,1
3,3,3,3,0,0,0,0,0,0,0,4,3,3,3,1,1
1,1,1,1,0,0,0,0,0,0,0,4,3,3,3,1,1
1,1,1,1,1,1,1,0,0,0,3,3,3,3,3,1,1
endlayer

layer
1,1,3,3,3,3,3,0,0,0,1,1,1,1,1,1,1
1,1,2,2,6,0,0,0,0,0,0,0,0,1,1,1,1
1,1,2,2,6,0,0,0,0,0,0,0,0,3,2,2,3
1,1,3,3,8,0,0,0,0,0,0,0,0,3,2,2,3
1,0,0,0,0,0,0,0,0,0,0,0,0,8,5,5,3
1,0,0,0,0,0,0,0,0,0,0,0,0,0,0,0,3
1,0,0,0,0,0,0,0,0,0,0,0,0,0,0,0,3
0,0,0,0,0,0,0,0,0,0,0,0,0,0,0,0,0
0,0,0,0,0,0,0,0,0,0,0,0,0,0,0,0,0
0,0,0,0,0,0,0,0,0,0,0,0,0,0,0,0,0
3,0,0,0,0,0,0,0,0,0,0,0,0,0,0,0,1
3,0,0,0,0,0,0,0,0,0,0,0,0,0,0,0,1
3,7,7,8,0,0,0,0,0,0,0,0,0,0,0,0,1
3,2,2,3,0,0,0,0,0,0,0,0,8,3,3,1,1
3,2,2,3,0,0,0,0,0,0,0,0,4,2,2,1,1
1,1,1,1,0,0,0,0,0,0,0,0,4,2,2,1,1
1,1,1,1,1,1,1,0,0,0,3,3,3,3,3,1,1
endlayer

layer
1,1,3,3,3,3,3,0,0,0,1,1,1,1,1,1,1
1,1,0,0,0,0,0,0,0,0,0,0,9,1,1,1,1
1,1,0,0,0,0,0,0,0,0,0,0,9,6,0,0,3
1,1,7,7,8,0,0,0,0,0,0,0,9,6,0,0,3
1,10,10,10,0,0,0,0,0,0,0,0,0,8,0,0,3
1,0,0,0,0,0,0,0,0,0,0,0,0,0,0,0,3
1,0,0,0,0,0,0,0,0,0,0,0,0,0,0,0,3
0,0,0,0,0,0,0,0,0,0,0,0,0,0,0,0,0
0,0,0,0,0,0,0,0,0,0,0,0,0,0,0,0,0
0,0,0,0,0,0,0,0,0,0,0,0,0,0,0,0,0
3,0,0,0,0,0,0,0,0,0,0,0,0,0,0,0,1
3,0,0,0,0,0,0,0,0,0,0,0,0,0,0,0,1
3,0,0,8,0,0,0,0,0,0,0,0,0,11,11,11,1
3,0,0,4,12,0,0,0,0,0,0,0,8,5,5,1,1
3,0,0,4,12,0,0,0,0,0,0,0,0,0,0,1,1
1,1,1,1,12,0,0,0,0,0,0,0,0,0,0,1,1
1,1,1,1,1,1,1,0,0,0,3,3,3,3,3,1,1
endlayer

layer
1,1,3,3,3,3,3,0,0,0,1,1,1,1,1,1,1
1,1,0,0,0,0,0,0,0,0,0,9,6,1,1,1,1
1,1,0,0,0,0,0,0,0,0,0,9,6,0,0,0,3
1,1,0,0,8,0,0,0,0,0,0,9,6,0,0,0,3
1,7,7,7,0,0,0,0,0,0,0,0,0,8,0,0,3
1,10,10,10,0,0,0,0,0,0,0,0,0,0,0,0,3
1,0,0,0,0,0,0,0,0,0,0,0,0,0,0,0,3
0,0,0,0,0,0,0,0,0,0,0,0,0,0,0,0,0
0,0,0,0,0,0,0,0,0,0,0,0,0,0,0,0,0
0,0,0,0,0,0,0,0,0,0,0,0,0,0,0,0,0
3,0,0,0,0,0,0,0,0,0,0,0,0,0,0,0,1
3,0,0,0,0,0,0,0,0,0,0,0,0,11,11,11,1
3,0,0,8,0,0,0,0,0,0,0,0,0,5,5,5,1
3,0,0,0,4,12,0,0,0,0,0,0,8,0,0,1,1
3,0,0,0,4,12,0,0,0,0,0,0,0,0,0,1,1
1,1,1,1,4,12,0,0,0,0,0,0,0,0,0,1,1
1,1,1,1,1,1,1,0,0,0,3,3,3,3,3,1,1
endlayer

layer
1,1,3,3,3,3,3,2,2,2,1,1,1,1,1,1,1
1,1,0,0,0,13,13,2,2,2,2,6,0,1,1,1,1
1,1,0,0,0,13,13,2,5,2,2,6,0,0,0,0,3
1,1,0,0,8,2,2,2,2,2,2,6,0,0,0,0,3
1,0,0,0,4,2,5,7,7,7,5,7,7,8,0,0,3
1,7,7,7,4,2,2,7,2,7,2,2,2,2,13,13,3
1,2,2,2,6,2,2,2,7,2,2,2,4,2,13,13,3
2,2,2,2,4,4,2,6,5,4,2,6,6,2,2,2,2
2,2,6,2,4,2,4,6,14,4,6,2,6,2,4,2,2
2,2,2,2,4,4,2,6,7,4,2,6,6,2,2,2,2
3,13,13,2,6,2,2,2,5,2,2,2,4,2,2,2,1
3,13,13,2,2,2,2,5,2,5,2,2,6,5,5,5,1
3,0,0,8,5,5,7,5,5,5,7,2,6,0,0,0,1
3,0,0,0,0,4,2,2,2,2,2,2,8,0,0,1,1
3,0,0,0,0,4,2,2,7,2,13,13,0,0,0,1,1
1,1,1,1,0,4,2,2,2,2,13,13,0,0,0,1,1
1,1,1,1,1,1,1,2,2,2,3,3,3,3,3,1,1
endlayer

layer
1,1,3,3,3,3,3,0,0,0,1,1,1,1,1,1,1
1,1,0,0,9,3,0,0,0,0,0,0,0,1,1,1,1
1,1,0,0,9,6,0,0,0,0,0,0,0,0,0,0,3
1,1,0,0,0,0,0,0,0,0,0,0,0,0,0,0,3
1,0,0,0,0,0,0,0,0,0,0,0,0,0,11,11,3
1,0,0,0,0,0,0,0,0,0,0,0,0,0,5,3,3
1,0,0,0,0,0,0,0,0,0,0,0,0,0,0,0,3
0,0,0,0,0,0,0,0,0,0,0,0,0,0,0,0,0
0,0,0,0,0,0,0,0,0,0,0,0,0,0,0,0,0
0,0,0,0,0,0,0,0,0,0,0,0,0,0,0,0,0
3,0,0,0,0,0,0,0,0,0,0,0,0,0,0,0,1
3,3,7,0,0,0,0,0,0,0,0,0,0,0,0,0,1
3,10,10,0,0,0,0,0,0,0,0,0,0,0,0,0,1
3,0,0,0,0,0,0,0,0,0,0,0,0,0,0,1,1
3,0,0,0,0,0,0,0,0,0,0,4,12,0,0,1,1
1,1,1,1,0,0,0,0,0,0,0,3,12,0,0,1,1
1,1,1,1,1,1,1,0,0,0,3,3,3,3,3,1,1
endlayer

layer
1,1,3,3,3,3,3,0,0,0,1,1,1,1,1,1,1
1,1,10,9,3,3,0,0,0,0,0,0,0,1,1,1,1
1,1,0,9,6,0,0,0,0,0,0,0,0,0,0,9,3
1,1,0,0,0,0,0,0,0,0,0,0,0,0,11,9,3
1,0,0,0,0,0,0,0,0,0,0,0,0,0,5,3,3
1,0,0,0,0,0,0,0,0,0,0,0,0,0,0,3,3
1,0,0,0,0,0,0,0,0,0,0,0,0,0,0,0,3
0,0,0,0,0,0,0,0,0,0,0,0,0,0,0,0,0
0,0,0,0,0,0,0,0,0,0,0,0,0,0,0,0,0
0,0,0,0,0,0,0,0,0,0,0,0,0,0,0,0,0
3,0,0,0,0,0,0,0,0,0,0,0,0,0,0,0,1
3,3,0,0,0,0,0,0,0,0,0,0,0,0,0,0,1
3,3,7,0,0,0,0,0,0,0,0,0,0,0,0,0,1
3,10,10,0,0,0,0,0,0,0,0,0,0,0,0,1,1
3,12,0,0,0,0,0,0,0,0,0,0,4,12,0,1,1
1,1,1,1,0,0,0,0,0,0,0,3,3,3,11,1,1
1,1,1,1,1,1,1,0,0,0,3,3,3,3,3,1,1
endlayer

layer
1,1,3,3,3,3,3,0,0,0,1,1,1,1,1,1,1
1,1,3,3,3,3,0,0,0,0,0,0,0,1,1,1,1
1,1,10,6,0,0,0,0,0,0,0,0,0,0,9,3,3
1,1,0,0,0,0,0,0,0,0,0,0,0,0,5,3,3
1,0,0,0,0,0,0,0,0,0,0,0,0,0,0,3,3
1,0,0,0,0,0,0,0,0,0,0,0,0,0,0,3,3
1,0,0,0,0,0,0,0,0,0,0,0,0,0,0,0,3
0,0,0,0,0,0,0,0,0,0,0,0,0,0,0,0,0
0,0,0,0,0,0,0,0,0,0,0,0,0,0,0,0,0
0,0,0,0,0,0,0,0,0,0,0,0,0,0,0,0,0
3,0,0,0,0,0,0,0,0,0,0,0,0,0,0,0,1
3,3,0,0,0,0,0,0,0,0,0,0,0,0,0,0,1
3,3,0,0,0,0,0,0,0,0,0,0,0,0,0,0,1
3,3,7,0,0,0,0,0,0,0,0,0,0,0,0,1,1
3,3,12,0,0,0,0,0,0,0,0,0,0,4,11,1,1
1,1,1,1,0,0,0,0,0,0,0,3,3,3,3,1,1
1,1,1,1,1,1,1,0,0,0,3,3,3,3,3,1,1
endlayer

layer
1,1,3,3,3,3,3,0,0,0,1,1,1,1,1,1,1
1,1,5,5,3,3,0,0,0,0,0,0,0,1,1,1,1
1,1,0,0,0,0,0,0,0,0,0,0,0,0,0,4,3
1,1,0,0,0,0,0,0,0,0,0,0,0,0,0,4,3
1,0,0,0,0,0,0,0,0,0,0,0,0,0,0,3,3
1,0,0,0,0,0,0,0,0,0,0,0,0,0,0,3,3
1,0,0,0,0,0,0,0,0,0,0,0,0,0,0,0,3
0,0,0,0,0,0,0,0,0,0,0,0,0,0,0,0,0
0,0,0,0,0,0,0,0,0,0,0,0,0,0,0,0,0
0,0,0,0,0,0,0,0,0,0,0,0,0,0,0,0,0
3,0,0,0,0,0,0,0,0,0,0,0,0,0,0,0,1
3,3,0,0,0,0,0,0,0,0,0,0,0,0,0,0,1
3,3,0,0,0,0,0,0,0,0,0,0,0,0,0,0,1
3,6,0,0,0,0,0,0,0,0,0,0,0,0,0,1,1
3,6,0,0,0,0,0,0,0,0,0,0,0,0,0,1,1
1,1,1,1,0,0,0,0,0,0,0,3,3,7,7,1,1
1,1,1,1,1,1,1,0,0,0,3,3,3,3,3,1,1
endlayer

layer
1,1,3,3,3,3,3,0,0,0,1,1,1,1,1,1,1
1,1,0,0,4,3,0,0,0,0,0,0,0,1,1,1,1
1,1,0,0,0,0,0,0,0,0,0,0,0,0,0,0,3
1,1,0,0,0,0,0,0,0,0,0,0,0,0,0,0,3
1,0,0,0,0,0,0,0,0,0,0,0,0,0,0,7,3
1,0,0,0,0,0,0,0,0,0,0,0,0,0,0,3,3
1,0,0,0,0,0,0,0,0,0,0,0,0,0,0,0,3
0,0,0,0,0,0,0,0,0,0,0,0,0,0,0,0,0
0,0,0,0,0,0,0,0,0,0,0,0,0,0,0,0,0
0,0,0,0,0,0,0,0,0,0,0,0,0,0,0,0,0
3,0,0,0,0,0,0,0,0,0,0,0,0,0,0,0,1
3,3,0,0,0,0,0,0,0,0,0,0,0,0,0,0,1
3,5,0,0,0,0,0,0,0,0,0,0,0,0,0,0,1
3,0,0,0,0,0,0,0,0,0,0,0,0,0,0,1,1
3,0,0,0,0,0,0,0,0,0,0,0,0,0,0,1,1
1,1,1,1,0,0,0,0,0,0,0,3,6,0,0,1,1
1,1,1,1,1,1,1,0,0,0,3,3,3,3,3,1,1
endlayer

layer
1,1,3,3,3,3,3,0,0,0,1,1,1,1,1,1,1
1,1,0,0,0,4,12,0,0,0,0,0,0,1,1,1,1
1,1,0,0,0,0,0,0,0,0,0,0,0,0,0,0,3
1,1,0,0,0,0,0,0,0,0,0,0,0,0,0,0,3
1,0,0,0,0,0,0,0,0,0,0,0,0,0,0,0,3
1,0,0,0,0,0,0,0,0,0,0,0,0,0,0,7,3
1,0,0,0,0,0,0,0,0,0,0,0,0,0,0,10,3
0,0,0,0,0,0,0,0,0,0,0,0,0,0,0,0,0
0,0,0,0,0,0,0,0,0,0,0,0,0,0,0,0,0
0,0,0,0,0,0,0,0,0,0,0,0,0,0,0,0,0
3,11,0,0,0,0,0,0,0,0,0,0,0,0,0,0,1
3,5,0,0,0,0,0,0,0,0,0,0,0,0,0,0,1
3,0,0,0,0,0,0,0,0,0,0,0,0,0,0,0,1
3,0,0,0,0,0,0,0,0,0,0,0,0,0,0,1,1
3,0,0,0,0,0,0,0,0,0,0,0,0,0,0,1,1
1,1,1,1,0,0,0,0,0,0,9,6,0,0,0,1,1
1,1,1,1,1,1,1,0,0,0,3,3,3,3,3,1,1
endlayer

layer
1,1,3,3,3,3,3,3,3,3,1,1,1,1,1,1,1
1,1,0,0,0,0,4,12,13,13,10,10,3,1,1,1,1
1,1,0,0,0,0,0,0,0,0,0,0,13,0,0,0,3
1,1,0,0,0,0,0,0,0,0,0,0,0,0,0,0,3
1,3,13,0,0,0,0,0,0,0,0,0,0,0,0,0,3
1,12,0,0,0,0,0,0,0,0,0,0,0,0,0,0,3
1,12,0,0,0,0,0,0,0,0,0,0,0,0,0,7,3
3,13,0,0,0,0,0,0,0,0,0,0,0,0,0,10,3
3,13,0,0,0,0,0,0,0,0,0,0,0,0,0,13,3
3,11,0,0,0,0,0,0,0,0,0,0,0,0,0,13,3
3,5,0,0,0,0,0,0,0,0,0,0,0,0,0,9,1
3,0,0,0,0,0,0,0,0,0,0,0,0,0,0,9,1
3,0,0,0,0,0,0,0,0,0,0,0,0,0,13,3,1
3,0,0,0,0,0,0,0,0,0,0,0,0,0,0,1,1
3,0,0,0,13,0,0,0,0,0,0,0,0,0,0,1,1
1,1,1,1,3,11,11,13,13,9,6,0,0,0,0,1,1
1,1,1,1,1,1,1,3,3,3,3,3,3,3,3,1,1
endlayer

layer
1,1,3,3,3,3,3,3,3,3,1,1,1,1,1,1,1
1,1,0,0,0,0,0,4,3,3,3,3,3,1,1,1,1
1,1,11,11,11,11,10,10,10,10,10,3,3,3,12,0,3
1,1,3,3,3,10,13,0,0,0,13,10,3,3,12,0,3
1,3,3,3,13,0,0,0,0,0,0,0,13,3,12,0,3
1,3,3,12,0,0,0,0,0,0,0,0,0,9,12,0,3
1,3,12,13,0,0,0,0,0,0,0,0,0,13,3,0,3
3,3,12,0,0,0,0,0,0,0,0,0,0,0,9,7,3
3,3,12,0,0,0,0,0,0,0,0,0,0,0,9,3,3
3,5,12,0,0,0,0,0,0,0,0,0,0,0,9,3,3
3,0,12,13,0,0,0,0,0,0,0,0,0,13,9,3,1
3,0,9,12,0,0,0,0,0,0,0,0,0,9,3,3,1
3,0,9,3,13,0,0,0,0,0,0,0,13,3,3,3,1
3,0,9,3,3,11,13,0,0,0,13,11,3,3,3,1,1
3,0,9,3,3,3,11,11,11,11,11,10,10,10,10,1,1
1,1,1,1,3,3,3,3,3,6,0,0,0,0,0,1,1
1,1,1,1,1,1,1,3,3,3,3,3,3,3,3,1,1
endlayer

layer
1,1,3,3,3,3,3,3,3,3,1,1,1,1,1,1,1
1,1,0,0,0,0,0,0,4,3,3,3,3,1,1,1,1
1,1,3,7,7,7,7,7,7,3,3,3,3,3,3,0,3
1,1,3,3,3,3,3,3,3,3,3,3,3,3,6,0,3
1,3,3,3,3,10,10,13,13,13,10,10,3,3,6,0,3
1,3,3,3,12,13,0,0,0,0,0,13,9,3,6,0,3
1,3,3,3,12,0,0,0,0,0,0,0,9,3,6,0,3
3,3,3,3,13,0,0,0,0,0,0,0,13,3,6,0,3
3,5,4,3,13,0,0,0,0,0,0,0,13,3,7,7,3
3,0,4,3,13,0,0,0,0,0,0,0,13,3,3,3,3
3,0,4,3,12,0,0,0,0,0,0,0,9,3,3,3,1
3,0,4,3,12,13,0,0,0,0,0,13,9,3,3,3,1
3,0,4,3,3,11,11,13,13,13,11,11,3,3,3,3,1
3,0,4,3,3,3,3,3,3,3,3,3,3,3,3,1,1
3,0,3,3,3,3,3,3,5,5,5,5,5,5,3,1,1
1,1,1,1,3,3,3,3,6,0,0,0,0,0,3,1,1
1,1,1,1,1,1,1,3,3,3,3,3,3,3,3,1,1
endlayer

layer
1,1,3,3,3,3,3,3,3,3,1,1,1,1,1,1,1
1,1,3,0,0,0,0,0,0,0,3,3,3,1,1,1,1
1,1,3,0,0,0,0,0,0,0,0,0,0,3,3,3,3
1,1,3,0,0,0,0,0,0,0,0,0,0,0,0,0,3
1,3,3,3,3,3,7,7,7,7,3,7,0,0,0,0,3
1,3,3,3,3,3,3,10,10,10,3,3,6,0,0,0,3
1,3,3,3,3,3,13,0,0,0,13,3,3,0,0,0,3
3,5,5,5,4,12,0,0,0,0,0,9,6,0,0,0,3
3,0,0,0,4,12,0,0,15,0,0,9,6,0,0,0,3
3,0,0,0,4,12,0,0,0,0,0,9,6,7,7,7,3
3,0,0,0,3,3,13,0,0,0,13,3,3,3,3,3,1
3,0,0,0,4,3,3,11,11,11,3,3,3,3,3,3,1
3,0,0,0,0,5,3,5,5,5,5,3,3,3,3,3,1
3,0,0,0,0,0,0,0,0,0,0,0,0,0,3,1,1
3,3,3,3,0,0,0,0,0,0,0,0,0,0,3,1,1
1,1,1,1,3,3,3,0,0,0,0,0,0,0,3,1,1
1,1,1,1,1,1,1,3,3,3,3,3,3,3,3,1,1
endlayer

layer
1,1,3,3,3,3,3,3,3,3,1,1,1,1,1,1,1
1,1,3,0,0,0,0,0,0,0,3,3,3,1,1,1,1
1,1,3,0,0,0,0,0,0,0,0,0,0,3,3,3,3
1,1,3,0,0,0,0,0,0,0,0,0,0,0,0,0,3
1,3,3,3,3,3,0,0,0,0,3,0,0,0,0,0,3
1,3,3,3,3,3,3,7,7,7,3,3,0,0,0,0,3
1,3,5,5,3,3,3,3,3,3,3,3,3,0,0,0,3
3,0,0,0,0,4,3,12,10,10,3,6,0,0,0,0,3
3,0,0,0,0,4,3,12,3,9,3,6,0,0,0,0,3
3,0,0,0,0,4,3,11,11,11,3,6,0,0,0,0,3
3,0,0,0,3,3,3,3,3,3,3,3,3,7,7,3,1
3,0,0,0,0,3,3,5,5,5,3,3,3,3,3,3,1
3,0,0,0,0,0,3,0,0,0,0,3,3,3,3,3,1
3,0,0,0,0,0,0,0,0,0,0,0,0,0,3,1,1
3,3,3,3,0,0,0,0,0,0,0,0,0,0,3,1,1
1,1,1,1,3,3,3,0,0,0,0,0,0,0,3,1,1
1,1,1,1,1,1,1,3,3,3,3,3,3,3,3,1,1
endlayer

layer
1,1,3,3,3,3,3,3,3,3,1,1,1,1,1,1,1
1,1,3,0,0,0,0,0,0,0,3,3,3,1,1,1,1
1,1,3,0,0,0,0,0,0,0,0,0,0,3,3,3,3
1,1,3,0,0,0,0,0,0,0,0,0,0,0,0,0,3
1,3,3,3,3,3,0,0,0,0,3,0,0,0,0,0,3
1,3,5,5,3,3,3,0,0,0,3,3,0,0,0,0,3
1,3,0,0,3,3,3,0,0,0,3,3,3,0,0,0,3
3,0,0,0,0,0,0,0,0,0,0,0,0,0,0,0,3
3,0,0,0,0,0,0,0,0,0,0,0,0,0,0,0,3
3,0,0,0,0,0,0,0,0,0,0,0,0,0,0,0,3
3,0,0,0,3,3,3,0,0,0,3,3,3,0,0,3,1
3,0,0,0,0,3,3,0,0,0,3,3,3,7,7,3,1
3,0,0,0,0,0,3,0,0,0,0,3,3,3,3,3,1
3,0,0,0,0,0,0,0,0,0,0,0,0,0,3,1,1
3,3,3,3,0,0,0,0,0,0,0,0,0,0,3,1,1
1,1,1,1,3,3,3,0,0,0,0,0,0,0,3,1,1
1,1,1,1,1,1,1,3,3,3,3,3,3,3,3,1,1
endlayer

layer
1,1,3,3,3,3,3,3,3,3,1,1,1,1,1,1,1
1,1,3,0,0,0,0,0,0,0,3,3,3,1,1,1,1
1,1,3,0,0,0,0,0,0,0,0,0,0,3,3,3,3
1,1,3,0,0,0,0,0,0,0,0,0,0,0,0,0,3
1,3,3,3,3,3,0,0,0,0,3,11,0,0,0,0,3
1,3,0,0,4,3,3,0,0,0,3,3,12,0,0,0,3
1,3,0,0,4,3,3,0,0,0,3,3,3,0,0,0,3
3,0,0,0,0,0,0,0,0,0,0,0,0,0,0,0,3
3,0,0,0,0,0,0,0,0,0,0,0,0,0,0,0,3
3,0,0,0,0,0,0,0,0,0,0,0,0,0,0,0,3
3,0,0,0,3,3,3,0,0,0,3,3,6,0,0,3,1
3,0,0,0,9,3,3,0,0,0,3,3,6,0,0,3,1
3,0,0,0,0,10,3,0,0,0,0,3,3,3,3,3,1
3,0,0,0,0,0,0,0,0,0,0,0,0,0,3,1,1
3,3,3,3,0,0,0,0,0,0,0,0,0,0,3,1,1
1,1,1,1,3,3,3,0,0,0,0,0,0,0,3,1,1
1,1,1,1,1,1,1,3,3,3,3,3,3,3,3,1,1
endlayer

layer
1,1,3,3,3,3,3,3,3,3,1,1,1,1,1,1,1
1,1,3,12,10,10,10,10,10,10,3,3,3,1,1,1,1
1,1,3,12,0,0,0,0,0,0,10,10,10,3,3,3,3
1,1,3,11,11,11,12,0,0,0,11,11,0,10,10,9,3
1,3,3,3,3,3,12,0,0,0,3,3,11,0,0,9,3
1,3,0,0,0,4,3,0,0,0,3,3,3,12,0,9,3
1,3,0,0,0,4,3,0,0,0,3,3,3,12,0,9,3
3,12,0,0,0,0,0,0,0,0,0,0,0,0,0,9,3
3,12,0,0,0,0,0,0,0,0,0,0,0,0,0,9,3
3,12,0,0,0,0,0,0,0,0,0,0,0,0,0,9,3
3,12,0,9,3,3,3,0,0,0,3,6,0,0,0,3,1
3,12,0,9,3,3,3,0,0,0,3,6,0,0,0,3,1
3,12,0,0,10,3,3,0,0,0,0,3,3,3,3,3,1
3,12,11,11,0,10,10,0,0,0,0,10,10,9,3,1,1
3,3,3,3,11,11,11,0,0,0,0,0,0,9,3,1,1
1,1,1,1,3,3,3,11,11,11,11,11,11,11,3,1,1
1,1,1,1,1,1,1,3,3,3,3,3,3,3,3,1,1
endlayer

layer
1,1,3,3,3,3,3,3,3,3,1,1,1,1,1,1,1
1,1,3,3,3,3,3,3,3,3,3,3,3,1,1,1,1
1,1,3,3,3,3,3,10,10,9,3,3,3,3,3,3,3
1,1,3,3,3,3,3,12,0,9,3,3,3,3,3,3,3
1,3,3,3,3,3,3,12,0,9,3,3,3,3,3,3,3
1,3,0,0,0,0,4,12,0,9,3,3,3,3,3,3,3
1,3,0,0,0,0,4,12,0,9,3,3,3,3,3,3,3
3,3,0,0,0,9,10,12,0,10,10,10,10,10,10,3,3
3,3,0,0,0,0,0,0,0,0,0,0,0,0,0,3,3
3,3,11,11,11,11,11,12,0,9,11,12,0,0,0,3,3
3,3,3,3,3,3,3,12,0,9,6,0,0,0,0,3,1
3,3,3,3,3,3,3,12,0,9,6,0,0,0,0,3,1
3,3,3,3,3,3,3,12,0,9,3,3,3,3,3,3,1
3,3,3,3,3,3,3,12,0,9,3,3,3,3,3,1,1
3,3,3,3,3,3,3,11,11,11,3,3,3,3,3,1,1
1,1,1,1,3,3,3,3,3,3,3,3,3,3,3,1,1
1,1,1,1,1,1,1,3,3,3,3,3,3,3,3,1,1
endlayer

layer
1,1,1,1,1,1,1,1,1,1,1,1,1,1,1,1,1
1,1,1,3,3,3,3,3,3,3,3,3,3,1,1,1,1
1,1,1,3,3,3,3,3,3,3,3,3,3,1,1,1,1
1,1,1,3,3,3,3,3,3,3,3,3,3,3,3,3,1
1,3,3,3,3,3,3,3,3,3,3,3,3,3,3,3,1
1,3,12,0,0,0,0,4,3,3,3,3,3,3,3,3,1
1,3,12,0,0,0,0,4,3,3,3,3,3,3,3,3,1
1,3,12,0,9,3,3,3,3,3,3,3,3,3,3,3,1
1,3,11,11,11,3,3,3,3,3,3,10,10,10,10,3,1
1,3,3,3,3,3,3,3,3,3,3,3,12,0,9,3,1
1,3,3,3,3,3,3,3,3,6,0,0,0,0,9,3,1
1,3,3,3,3,3,3,3,3,6,0,0,0,0,9,3,1
1,3,3,3,3,3,3,3,3,3,3,3,3,3,3,3,1
1,3,3,3,3,3,3,3,3,3,3,3,3,3,1,1,1
1,1,1,1,3,3,3,3,3,3,3,3,3,3,1,1,1
1,1,1,1,3,3,3,3,3,3,3,3,3,3,1,1,1
1,1,1,1,1,1,1,1,1,1,1,1,1,1,1,1,1
endlayer

layer
1,1,1,1,1,1,1,1,1,1,1,1,1,1,1,1,1
1,1,1,1,1,1,1,1,1,1,1,1,1,1,1,1,1
1,1,1,1,1,1,1,1,3,3,3,3,3,1,1,1,1
1,1,1,3,3,3,3,3,3,3,3,3,3,3,1,1,1
1,1,3,3,3,3,3,3,3,3,3,3,3,3,1,1,1
1,1,3,12,0,0,0,0,4,3,3,3,3,3,1,1,1
1,1,3,12,0,0,0,0,4,3,3,3,3,3,1,1,1
1,1,3,3,3,3,7,7,7,3,3,3,3,3,1,1,1
1,1,3,3,3,3,3,3,3,3,3,3,3,3,3,1,1
1,1,1,3,3,3,3,3,5,5,5,3,3,3,3,1,1
1,1,1,3,3,3,3,3,6,0,0,0,0,9,3,1,1
1,1,1,3,3,3,3,3,6,0,0,0,0,9,3,1,1
1,1,1,3,3,3,3,3,3,3,3,3,3,3,3,1,1
1,1,1,3,3,3,3,3,3,3,3,3,3,3,1,1,1
1,1,1,1,3,3,3,3,3,1,1,1,1,1,1,1,1
1,1,1,1,1,1,1,1,1,1,1,1,1,1,1,1,1
1,1,1,1,1,1,1,1,1,1,1,1,1,1,1,1,1
endlayer

layer
1,1,1,1,1,1,1,1,1,1,1,1,1,1,1,1,1
1,1,1,1,1,1,1,1,1,1,1,1,1,1,1,1,1
1,1,1,1,1,1,1,1,1,1,1,1,1,1,1,1,1
1,1,1,3,3,3,3,3,3,3,3,3,3,3,1,1,1
1,1,1,3,3,3,3,3,3,3,3,3,3,3,1,1,1
1,1,1,3,12,0,0,0,0,4,0,0,0,3,1,1,1
1,1,1,3,12,0,0,0,0,4,3,3,3,3,1,1,1
1,1,1,3,0,0,0,0,0,0,0,0,17,3,1,1,1
1,1,1,3,0,0,0,0,0,0,0,0,0,3,1,1,1
1,1,1,3,0,0,0,0,0,0,0,0,0,3,1,1,1
1,1,1,3,3,3,3,6,0,0,0,0,9,3,1,1,1
1,1,1,3,0,0,0,6,0,0,0,0,9,3,1,1,1
1,1,1,3,3,3,3,3,3,3,3,3,3,3,1,1,1
1,1,1,3,3,3,3,3,3,3,3,3,3,3,1,1,1
1,1,1,1,1,1,1,1,1,1,1,1,1,1,1,1,1
1,1,1,1,1,1,1,1,1,1,1,1,1,1,1,1,1
1,1,1,1,1,1,1,1,1,1,1,1,1,1,1,1,1
endlayer

layer
1,1,1,1,1,1,1,1,1,1,1,1,1,1,1,1,1
1,1,1,1,1,1,1,1,1,1,1,1,1,1,1,1,1
1,1,1,1,1,1,1,1,1,1,1,1,1,1,1,1,1
1,1,1,3,3,3,3,3,3,3,3,3,3,3,1,1,1
1,1,1,3,3,3,3,3,3,3,3,3,3,3,1,1,1
1,1,1,3,3,12,0,0,0,0,4,0,0,3,1,1,1
1,1,1,3,3,12,0,0,0,0,4,3,3,3,1,1,1
1,1,1,3,0,0,0,0,0,0,0,0,0,3,1,1,1
1,1,1,3,0,0,0,0,0,0,0,0,0,3,1,1,1
1,1,1,3,0,0,0,0,0,0,0,0,0,3,1,1,1
1,1,1,3,3,3,6,0,0,0,0,9,3,3,1,1,1
1,1,1,3,0,0,6,0,0,0,0,9,3,3,1,1,1
1,1,1,3,3,3,3,3,3,3,3,3,3,3,1,1,1
1,1,1,3,3,3,3,3,3,3,3,3,3,3,1,1,1
1,1,1,1,1,1,1,1,1,1,1,1,1,1,1,1,1
1,1,1,1,1,1,1,1,1,1,1,1,1,1,1,1,1
1,1,1,1,1,1,1,1,1,1,1,1,1,1,1,1,1
endlayer

layer
1,1,1,1,1,1,1,1,1,1,1,1,1,1,1,1,1
1,1,1,1,1,1,1,1,1,1,1,1,1,1,1,1,1
1,1,1,1,1,1,1,1,1,1,1,1,1,1,1,1,1
1,1,1,3,3,3,3,3,3,3,3,3,3,3,1,1,1
1,1,1,3,3,3,3,3,3,3,3,3,3,3,1,1,1
1,1,1,3,3,3,12,0,0,0,0,4,3,3,1,1,1
1,1,1,3,3,3,0,0,0,0,0,4,3,3,1,1,1
1,1,1,3,0,0,0,0,0,0,0,10,10,3,1,1,1
1,1,1,3,0,0,0,0,0,0,0,0,0,3,1,1,1
1,1,1,3,11,11,0,0,0,0,0,0,0,3,1,1,1
1,1,1,3,3,6,0,0,0,0,0,3,3,3,1,1,1
1,1,1,3,3,6,0,0,0,0,9,3,3,3,1,1,1
1,1,1,3,3,3,3,3,3,3,3,3,3,3,1,1,1
1,1,1,3,3,3,3,3,3,3,3,3,3,3,1,1,1
1,1,1,1,1,1,1,1,1,1,1,1,1,1,1,1,1
1,1,1,1,1,1,1,1,1,1,1,1,1,1,1,1,1
1,1,1,1,1,1,1,1,1,1,1,1,1,1,1,1,1
endlayer

layer
1,1,1,1,1,1,1,1,1,1,1,1,1,1,1,1,1
1,1,1,1,1,1,1,1,1,1,1,1,1,1,1,1,1
1,1,1,1,1,1,1,1,1,1,1,1,1,1,1,1,1
1,1,1,3,3,3,3,3,3,3,3,3,3,3,1,1,1
1,1,1,3,3,3,3,3,3,3,3,3,3,3,1,1,1
1,1,1,3,3,3,3,12,0,0,0,0,0,3,1,1,1
1,1,1,3,3,3,0,0,0,0,0,0,0,3,1,1,1
1,1,1,3,12,0,0,0,0,0,0,7,7,3,1,1,1
1,1,1,3,12,11,0,0,0,0,0,10,9,3,1,1,1
1,1,1,3,5,5,0,0,0,0,0,0,9,3,1,1,1
1,1,1,3,0,0,0,0,0,0,0,3,3,3,1,1,1
1,1,1,3,0,0,0,0,0,9,3,3,3,3,1,1,1
1,1,1,3,3,3,3,3,3,3,3,3,3,3,1,1,1
1,1,1,3,3,3,3,3,3,3,3,3,3,3,1,1,1
1,1,1,1,1,1,1,1,1,1,1,1,1,1,1,1,1
1,1,1,1,1,1,1,1,1,1,1,1,1,1,1,1,1
1,1,1,1,1,1,1,1,1,1,1,1,1,1,1,1,1
endlayer

layer
1,1,1,1,1,1,1,1,1,1,1,1,1,1,1,1,1
1,1,1,1,1,1,1,1,1,1,1,1,1,1,1,1,1
1,1,1,1,1,1,1,1,1,1,1,1,1,1,1,1,1
1,1,1,3,3,3,3,3,3,3,3,3,3,3,1,1,1
1,1,1,3,3,3,3,3,3,3,3,3,3,3,1,1,1
1,1,1,3,3,3,3,3,12,0,0,0,0,3,1,1,1
1,1,1,3,3,3,0,0,0,0,0,0,0,3,1,1,1
1,1,1,3,3,3,0,0,0,0,0,0,0,3,1,1,1
1,1,1,3,5,5,0,0,0,0,0,7,7,3,1,1,1
1,1,1,3,0,0,0,0,0,0,0,3,3,3,1,1,1
1,1,1,3,0,0,0,0,0,0,0,3,3,3,1,1,1
1,1,1,3,0,0,0,0,9,3,3,3,3,3,1,1,1
1,1,1,3,3,3,3,3,3,3,3,3,3,3,1,1,1
1,1,1,3,3,3,3,3,3,3,3,3,3,3,1,1,1
1,1,1,1,1,1,1,1,1,1,1,1,1,1,1,1,1
1,1,1,1,1,1,1,1,1,1,1,1,1,1,1,1,1
1,1,1,1,1,1,1,1,1,1,1,1,1,1,1,1,1
endlayer

layer
1,1,1,1,1,1,1,1,1,1,1,1,1,1,1,1,1
1,1,1,1,1,1,1,1,1,1,1,1,1,1,1,1,1
1,1,1,1,1,1,1,1,1,1,1,1,1,1,1,1,1
1,1,1,3,3,3,3,3,3,3,3,3,3,3,1,1,1
1,1,1,3,3,3,3,3,3,3,3,3,3,3,1,1,1
1,1,1,3,3,3,3,3,3,12,0,0,0,3,1,1,1
1,1,1,3,3,3,0,0,0,0,0,0,0,3,1,1,1
1,1,1,3,5,5,0,0,0,0,0,0,0,3,1,1,1
1,1,1,3,0,0,0,0,0,0,0,0,0,3,1,1,1
1,1,1,3,0,0,0,0,0,0,0,7,7,3,1,1,1
1,1,1,3,0,0,0,0,0,0,0,3,3,3,1,1,1
1,1,1,3,0,0,0,9,3,3,3,3,3,3,1,1,1
1,1,1,3,3,3,3,3,3,3,3,3,3,3,1,1,1
1,1,1,3,3,3,3,3,3,3,3,3,3,3,1,1,1
1,1,1,1,1,1,1,1,1,1,1,1,1,1,1,1,1
1,1,1,1,1,1,1,1,1,1,1,1,1,1,1,1,1
1,1,1,1,1,1,1,1,1,1,1,1,1,1,1,1,1
endlayer

layer
1,1,1,1,1,1,1,1,1,1,1,1,1,1,1,1,1
1,1,1,1,1,1,1,1,1,1,1,1,1,1,1,1,1
1,1,1,1,1,1,1,1,1,1,1,1,1,1,1,1,1
1,1,1,3,3,3,3,3,3,3,3,3,3,3,1,1,1
1,1,1,3,3,3,3,3,3,3,3,3,3,3,1,1,1
1,1,1,3,3,3,3,3,3,3,12,0,0,3,1,1,1
1,1,1,3,5,5,0,0,0,0,0,0,0,3,1,1,1
1,1,1,3,0,0,0,0,0,0,0,0,0,3,1,1,1
1,1,1,3,0,0,0,0,0,0,0,0,0,3,1,1,1
1,1,1,3,0,0,0,0,0,0,0,0,0,3,1,1,1
1,1,1,3,0,0,0,0,0,0,0,7,7,3,1,1,1
1,1,1,3,0,0,9,3,3,3,3,3,3,3,1,1,1
1,1,1,3,3,3,3,3,3,3,3,3,3,3,1,1,1
1,1,1,3,3,3,3,3,3,3,3,3,3,3,1,1,1
1,1,1,1,1,1,1,1,1,1,1,1,1,1,1,1,1
1,1,1,1,1,1,1,1,1,1,1,1,1,1,1,1,1
1,1,1,1,1,1,1,1,1,1,1,1,1,1,1,1,1
endlayer

layer
1,1,1,1,1,1,1,1,1,1,1,1,1,1,1,1,1
1,1,1,1,1,1,1,1,1,1,1,1,1,1,1,1,1
1,1,1,1,1,1,1,1,1,1,1,1,1,1,1,1,1
1,1,1,3,3,3,3,3,3,3,3,3,3,3,1,1,1
1,1,1,3,16,0,4,3,3,3,3,3,3,3,1,1,1
1,1,1,3,0,0,4,3,3,3,3,12,10,3,1,1,1
1,1,1,3,0,0,0,0,0,0,0,0,0,3,1,1,1
1,1,1,3,0,0,0,0,0,0,0,0,0,3,1,1,1
1,1,1,3,0,0,0,0,0,0,0,0,0,3,1,1,1
1,1,1,3,0,0,0,0,0,0,0,0,0,3,1,1,1
1,1,1,3,0,0,0,0,0,0,0,0,0,3,1,1,1
1,1,1,3,11,9,3,3,3,3,6,0,0,3,1,1,1
1,1,1,3,3,3,3,3,3,3,6,0,16,3,1,1,1
1,1,1,3,3,3,3,3,3,3,3,3,3,3,1,1,1
1,1,1,1,1,1,1,1,1,1,1,1,1,1,1,1,1
1,1,1,1,1,1,1,1,1,1,1,1,1,1,1,1,1
1,1,1,1,1,1,1,1,1,1,1,1,1,1,1,1,1
endlayer

layer
1,1,1,1,1,1,1,1,1,1,1,1,1,1,1,1,1
1,1,1,1,1,1,1,1,1,1,1,1,1,1,1,1,1
1,1,1,1,1,1,1,1,1,1,1,1,1,1,1,1,1
1,1,1,3,3,3,3,3,3,3,3,3,3,3,1,1,1
1,1,1,3,0,0,0,4,3,3,3,3,3,3,1,1,1
1,1,1,3,0,0,0,4,3,3,3,3,3,3,1,1,1
1,1,1,3,0,0,0,0,0,0,0,10,10,3,1,1,1
1,1,1,3,0,0,0,0,0,0,0,0,0,3,1,1,1
1,1,1,3,0,0,0,0,0,0,0,0,0,3,1,1,1
1,1,1,3,0,0,0,0,0,0,0,0,0,3,1,1,1
1,1,1,3,11,11,0,0,0,0,0,0,0,3,1,1,1
1,1,1,3,3,3,3,3,3,6,0,0,0,3,1,1,1
1,1,1,3,3,3,3,3,3,6,0,0,0,3,1,1,1
1,1,1,3,3,3,3,3,3,3,3,3,3,3,1,1,1
1,1,1,1,1,1,1,1,1,1,1,1,1,1,1,1,1
1,1,1,1,1,1,1,1,1,1,1,1,1,1,1,1,1
1,1,1,1,1,1,1,1,1,1,1,1,1,1,1,1,1
endlayer

layer
1,1,1,1,1,1,1,1,1,1,1,1,1,1,1,1,1
1,1,1,1,1,1,1,1,1,1,1,1,1,1,1,1,1
1,1,1,1,1,1,1,1,1,1,1,1,1,1,1,1,1
1,1,1,3,3,3,3,3,3,3,3,3,3,3,1,1,1
1,1,1,3,0,0,0,0,4,3,3,3,3,3,1,1,1
1,1,1,3,0,0,0,0,4,3,3,3,3,3,1,1,1
1,1,1,3,0,0,0,0,0,0,0,3,3,3,1,1,1
1,1,1,3,0,0,0,0,0,0,0,10,10,3,1,1,1
1,1,1,3,0,0,0,0,0,0,0,0,0,3,1,1,1
1,1,1,3,11,11,0,0,0,0,0,0,0,3,1,1,1
1,1,1,3,3,3,0,0,0,0,0,0,0,3,1,1,1
1,1,1,3,3,3,3,3,6,0,0,0,0,3,1,1,1
1,1,1,3,3,3,3,3,6,0,0,0,0,3,1,1,1
1,1,1,3,3,3,3,3,3,3,3,3,3,3,1,1,1
1,1,1,1,1,1,1,1,1,1,1,1,1,1,1,1,1
1,1,1,1,1,1,1,1,1,1,1,1,1,1,1,1,1
1,1,1,1,1,1,1,1,1,1,1,1,1,1,1,1,1
endlayer

layer
1,1,1,1,1,1,1,1,1,1,1,1,1,1,1,1,1
1,1,1,1,1,1,1,1,1,1,1,1,1,1,1,1,1
1,1,1,1,1,1,1,1,1,1,1,1,1,1,1,1,1
1,1,1,3,3,3,3,3,3,3,3,3,3,3,1,1,1
1,1,1,3,0,0,0,0,0,4,3,3,3,3,1,1,1
1,1,1,3,0,0,0,0,0,4,3,3,3,3,1,1,1
1,1,1,3,0,0,0,0,0,0,0,3,3,3,1,1,1
1,1,1,3,0,0,0,0,0,0,0,3,3,3,1,1,1
1,1,1,3,11,11,0,0,0,0,0,10,10,3,1,1,1
1,1,1,3,3,3,0,0,0,0,0,0,0,3,1,1,1
1,1,1,3,3,3,0,0,0,0,0,0,0,3,1,1,1
1,1,1,3,3,3,3,6,0,0,0,0,0,3,1,1,1
1,1,1,3,3,3,3,6,0,0,0,0,0,3,1,1,1
1,1,1,3,3,3,3,3,3,3,3,3,3,3,1,1,1
1,1,1,1,1,1,1,1,1,1,1,1,1,1,1,1,1
1,1,1,1,1,1,1,1,1,1,1,1,1,1,1,1,1
1,1,1,1,1,1,1,1,1,1,1,1,1,1,1,1,1
endlayer

layer
1,1,1,1,1,1,1,1,1,1,1,1,1,1,1,1,1
1,1,1,1,1,1,1,1,1,1,1,1,1,1,1,1,1
1,1,1,1,1,1,1,1,1,1,1,1,1,1,1,1,1
1,1,1,3,3,3,3,3,3,3,3,3,3,3,1,1,1
1,1,1,3,0,0,0,0,0,0,4,3,3,3,1,1,1
1,1,1,3,0,0,0,0,0,0,4,3,3,3,1,1,1
1,1,1,3,0,0,0,0,0,0,0,3,3,3,1,1,1
1,1,1,3,11,11,0,0,0,0,0,3,3,3,1,1,1
1,1,1,3,3,3,0,0,0,0,0,3,3,3,1,1,1
1,1,1,3,3,3,0,0,0,0,0,10,10,3,1,1,1
1,1,1,3,3,3,0,0,0,0,0,0,0,3,1,1,1
1,1,1,3,3,3,6,0,0,0,0,0,0,3,1,1,1
1,1,1,3,3,3,6,0,0,0,0,0,0,3,1,1,1
1,1,1,3,3,3,3,3,3,3,3,3,3,3,1,1,1
1,1,1,1,1,1,1,1,1,1,1,1,1,1,1,1,1
1,1,1,1,1,1,1,1,1,1,1,1,1,1,1,1,1
1,1,1,1,1,1,1,1,1,1,1,1,1,1,1,1,1
endlayer

