
# Created by Ruins mod version 16.7 Ingame Parser
# authoring Player: lafuller

weight=1
embed_into_distance=3
acceptable_target_blocks=water
unacceptable_target_blocks=
biomesToSpawnIn=ocean,deep ocean,ocean oil field,kelp forest
dimensions=19,27,27
allowable_overhang=0
max_leveling=0
leveling_buffer=-1
preserve_water=0
preserve_lava=0

rule1=0,100,preserveBlock
rule2=0,100,minecraft:planks-5
rule3=0,100,minecraft:dark_oak_stairs-0
rule4=0,100,minecraft:dark_oak_stairs-2
rule5=0,100,minecraft:log2-1
rule6=0,100,minecraft:dark_oak_stairs-3
rule7=0,100,minecraft:dark_oak_stairs-1
rule8=0,100,minecraft:wooden_slab-5
rule9=0,100,ChestGenHook:chests/stronghold_crossing:5-2
rule10=0,100,minecraft:spruce_stairs-0
rule11=0,100,minecraft:spruce_stairs-3
rule12=0,100,minecraft:spruce_stairs-4
rule13=0,100,minecraft:planks-1
rule14=0,100,minecraft:spruce_stairs-6
rule15=0,100,minecraft:spruce_stairs-1
rule16=0,100,minecraft:wooden_slab-1
rule17=0,100,minecraft:spruce_stairs-7
rule18=0,100,minecraft:spruce_stairs-5
rule19=0,100,minecraft:spruce_stairs-2
rule20=0,100,minecraft:trapdoor-6
rule21=0,100,minecraft:wooden_slab-9
rule22=0,100,minecraft:trapdoor-11
rule23=0,100,minecraft:trapdoor-10
rule24=0,100,minecraft:trapdoor-8
rule25=0,100,minecraft:trapdoor-5
rule26=0,100,minecraft:trapdoor-9
rule27=0,100,minecraft:trapdoor-4
rule28=0,100,minecraft:trapdoor-7
rule29=0,100,minecraft:log-0
rule30=0,100,minecraft:wooden_slab-13
rule31=0,100,minecraft:dark_oak_fence-0
rule32=0,100,minecraft:dark_oak_stairs-5
rule33=0,100,minecraft:dark_oak_stairs-6
rule34=0,100,minecraft:ladder-5
rule35=0,100,minecraft:dark_oak_stairs-7
rule36=0,100,minecraft:spruce_fence-0
rule37=0,100,minecraft:dark_oak_stairs-4
rule38=0,100,minecraft:spruce_door-4
rule39=0,100,minecraft:crafting_table-0
rule40=0,100,ChestGenHook:chests/stronghold_library:5-4
rule41=0,100,minecraft:trapdoor-14
rule42=0,100,minecraft:trapdoor-12
rule43=0,100,minecraft:spruce_door-8
rule44=0,100,minecraft:carpet-7
rule45=0,100,minecraft:carpet-8
rule46=0,100,minecraft:bookshelf-0
rule47=0,100,minecraft:wool-0
rule48=0,100,minecraft:dark_oak_fence_gate-1
rule49=0,100,minecraft:log-12
rule50=0,100,minecraft:dark_oak_fence_gate-0
rule51=0,100,minecraft:trapdoor-0
rule52=0,100,minecraft:dark_oak_fence_gate-3
rule53=0,100,minecraft:log2-13
rule54=0,100,minecraft:log2-9
rule55=0,100,minecraft:log2-5
rule56=0,100,minecraft:dark_oak_fence_gate-2

layer
1,1,1,1,1,1,1,1,1,1,1,1,1,1,1,1,1,1,1,1,1,1,1,1,1,1,1
1,1,1,1,1,1,1,1,1,1,1,1,1,1,1,1,1,1,1,1,1,1,1,1,1,1,1
1,1,1,1,1,1,1,1,1,1,1,1,1,1,1,1,1,1,1,1,1,1,1,1,1,1,1
1,1,1,1,1,1,1,1,1,1,1,1,1,1,1,1,1,1,1,1,1,1,1,1,1,1,1
1,1,1,1,1,1,1,1,1,1,1,1,1,1,1,1,1,1,1,1,1,1,1,1,1,1,1
1,1,1,1,1,1,1,1,1,1,1,1,1,1,1,1,1,1,1,1,1,1,1,1,1,1,1
1,1,1,1,1,1,1,1,1,1,1,1,1,1,1,1,1,1,1,2,2,1,1,1,1,1,1
1,1,1,1,1,1,1,1,1,1,1,1,1,1,1,1,1,1,2,2,2,1,1,1,1,1,1
1,1,1,1,1,1,1,1,1,1,1,1,1,1,1,1,1,2,2,2,1,1,1,1,1,1,1
1,1,1,1,1,1,1,1,1,1,1,1,1,1,1,1,2,2,2,1,1,1,1,1,1,1,1
1,1,1,1,1,1,1,1,1,1,1,1,1,1,1,2,2,2,1,1,1,1,1,1,1,1,1
1,1,1,1,1,1,1,1,1,1,1,1,1,1,2,2,2,1,1,1,1,1,1,1,1,1,1
1,1,1,1,1,1,1,1,1,1,1,1,1,2,2,2,1,1,1,1,1,1,1,1,1,1,1
1,1,1,1,1,1,1,1,1,1,1,1,2,2,2,1,1,1,1,1,1,1,1,1,1,1,1
1,1,1,1,1,1,1,1,1,1,1,2,2,2,1,1,1,1,1,1,1,1,1,1,1,1,1
1,1,1,1,1,1,1,1,1,1,2,2,2,1,1,1,1,1,1,1,1,1,1,1,1,1,1
1,1,1,1,1,1,1,1,1,2,2,2,1,1,1,1,1,1,1,1,1,1,1,1,1,1,1
1,1,1,1,1,1,1,1,2,2,2,1,1,1,1,1,1,1,1,1,1,1,1,1,1,1,1
1,1,1,1,1,1,1,2,2,2,1,1,1,1,1,1,1,1,1,1,1,1,1,1,1,1,1
1,1,1,1,1,1,2,2,2,1,1,1,1,1,1,1,1,1,1,1,1,1,1,1,1,1,1
1,1,1,1,1,2,2,2,1,1,1,1,1,1,1,1,1,1,1,1,1,1,1,1,1,1,1
1,1,1,1,1,2,2,1,1,1,1,1,1,1,1,1,1,1,1,1,1,1,1,1,1,1,1
1,1,1,1,1,1,1,1,1,1,1,1,1,1,1,1,1,1,1,1,1,1,1,1,1,1,1
1,1,1,1,1,1,1,1,1,1,1,1,1,1,1,1,1,1,1,1,1,1,1,1,1,1,1
1,1,1,1,1,1,1,1,1,1,1,1,1,1,1,1,1,1,1,1,1,1,1,1,1,1,1
1,1,1,1,1,1,1,1,1,1,1,1,1,1,1,1,1,1,1,1,1,1,1,1,1,1,1
1,1,1,1,1,1,1,1,1,1,1,1,1,1,1,1,1,1,1,1,1,1,1,1,1,1,1
endlayer

layer
1,1,1,1,1,1,1,1,1,1,1,1,1,1,1,1,1,1,1,1,1,1,1,1,1,1,1
1,1,1,1,1,1,1,1,1,1,1,1,1,1,1,1,1,1,1,1,1,1,1,1,1,1,1
1,1,1,1,1,1,1,1,1,1,1,1,1,1,1,1,1,1,1,1,1,1,1,1,1,1,1
1,1,1,1,1,1,1,1,1,1,1,1,1,1,1,1,1,1,1,1,1,1,1,1,1,1,1
1,1,1,1,1,1,1,1,1,1,1,1,1,1,1,1,1,1,1,1,2,2,2,1,1,1,1
1,1,1,1,1,1,1,1,1,1,1,1,1,1,1,1,1,1,2,2,3,2,2,1,1,1,1
1,1,1,1,1,1,1,1,1,1,1,1,1,1,1,1,1,2,6,6,5,4,2,1,1,1,1
1,1,1,1,1,1,1,1,1,1,1,1,1,1,1,1,2,4,3,8,7,2,1,1,1,1,1
1,1,1,1,1,1,1,1,1,1,1,1,1,1,1,2,2,6,2,4,7,2,1,1,1,1,1
1,1,1,1,1,1,1,1,1,1,1,1,1,1,2,4,4,2,7,3,2,1,1,1,1,1,1
1,1,1,1,1,1,1,1,1,1,1,1,1,2,2,6,2,3,2,2,1,1,1,1,1,1,1
1,1,1,1,1,1,1,1,1,1,1,1,2,4,3,5,4,3,2,1,1,1,1,1,1,1,1
1,1,1,1,1,1,1,1,1,1,1,2,2,6,2,7,2,2,1,1,1,1,1,1,1,1,1
1,1,1,1,1,1,1,1,1,1,2,4,4,2,7,3,2,1,1,1,1,1,1,1,1,1,1
1,1,1,1,1,1,1,1,1,2,2,6,2,3,2,2,1,1,1,1,1,1,1,1,1,1,1
1,1,1,1,1,1,1,1,2,4,3,2,7,3,2,1,1,1,1,1,1,1,1,1,1,1,1
1,1,1,1,1,1,1,2,2,6,5,4,2,2,1,1,1,1,1,1,1,1,1,1,1,1,1
1,1,1,1,1,1,2,4,4,2,7,3,2,1,1,1,1,1,1,1,1,1,1,1,1,1,1
1,1,1,1,1,2,2,6,2,3,2,2,1,1,1,1,1,1,1,1,1,1,1,1,1,1,1
1,1,1,1,1,2,3,2,7,3,2,1,1,1,1,1,1,1,1,1,1,1,1,1,1,1,1
1,1,1,1,2,2,2,4,2,2,1,1,1,1,1,1,1,1,1,1,1,1,1,1,1,1,1
1,1,1,1,2,2,2,2,2,1,1,1,1,1,1,1,1,1,1,1,1,1,1,1,1,1,1
1,1,1,1,2,2,2,1,1,1,1,1,1,1,1,1,1,1,1,1,1,1,1,1,1,1,1
1,1,1,1,1,1,1,1,1,1,1,1,1,1,1,1,1,1,1,1,1,1,1,1,1,1,1
1,1,1,1,1,1,1,1,1,1,1,1,1,1,1,1,1,1,1,1,1,1,1,1,1,1,1
1,1,1,1,1,1,1,1,1,1,1,1,1,1,1,1,1,1,1,1,1,1,1,1,1,1,1
1,1,1,1,1,1,1,1,1,1,1,1,1,1,1,1,1,1,1,1,1,1,1,1,1,1,1
endlayer

layer
1,1,1,1,1,1,1,1,1,1,1,1,1,1,1,1,1,1,1,1,1,1,1,1,1,1,1
1,1,1,1,1,1,1,1,1,1,1,1,1,1,1,1,1,1,1,1,1,1,1,1,1,1,1
1,1,1,1,1,1,1,1,1,1,1,1,1,1,1,1,1,1,1,1,1,1,1,1,1,1,1
1,1,1,1,1,1,1,1,1,1,1,1,1,1,1,1,1,1,1,1,2,7,7,7,1,1,1
1,1,1,1,1,1,1,1,1,1,1,1,1,1,1,1,1,1,2,7,0,0,0,6,1,1,1
1,1,1,1,1,1,1,1,1,1,1,1,1,1,1,1,1,2,9,0,0,0,0,6,1,1,1
1,1,1,1,1,1,1,1,1,1,1,1,1,1,1,1,2,0,0,0,5,0,0,2,1,1,1
1,1,1,1,1,1,1,1,1,1,1,1,1,1,1,2,0,0,0,0,0,0,6,1,1,1,1
1,1,1,1,1,1,1,1,1,1,1,1,1,1,2,0,0,0,0,0,0,10,2,1,1,1,1
1,1,1,1,1,1,1,1,1,1,1,1,1,2,0,0,0,0,0,0,0,2,1,1,1,1,1
1,1,1,1,1,1,1,1,1,1,1,1,2,0,0,0,0,0,0,0,2,1,1,1,1,1,1
1,1,1,1,1,1,1,1,1,1,1,2,0,0,0,5,0,0,0,2,1,1,1,1,1,1,1
1,1,1,1,1,1,1,1,1,1,2,0,0,0,0,0,0,0,2,1,1,1,1,1,1,1,1
1,1,1,1,1,1,1,1,1,2,0,0,0,0,0,0,0,2,1,1,1,1,1,1,1,1,1
1,1,1,1,1,1,1,1,2,0,0,0,0,0,0,0,2,1,1,1,1,1,1,1,1,1,1
1,1,1,1,1,1,1,2,0,0,0,0,0,0,0,2,1,1,1,1,1,1,1,1,1,1,1
1,1,1,1,1,1,2,0,0,0,5,0,0,0,2,1,1,1,1,1,1,1,1,1,1,1,1
1,1,1,1,1,2,0,0,0,0,0,0,0,2,1,1,1,1,1,1,1,1,1,1,1,1,1
1,1,1,1,2,4,0,0,0,0,0,0,2,1,1,1,1,1,1,1,1,1,1,1,1,1,1
1,1,1,1,2,0,0,0,0,0,11,2,1,1,1,1,1,1,1,1,1,1,1,1,1,1,1
1,1,1,2,4,0,0,0,0,0,2,1,1,1,1,1,1,1,1,1,1,1,1,1,1,1,1
1,1,1,2,4,0,0,0,3,2,1,1,1,1,1,1,1,1,1,1,1,1,1,1,1,1,1
1,1,1,2,4,3,3,2,2,1,1,1,1,1,1,1,1,1,1,1,1,1,1,1,1,1,1
1,1,1,2,2,2,2,1,1,1,1,1,1,1,1,1,1,1,1,1,1,1,1,1,1,1,1
1,1,1,1,1,1,1,1,1,1,1,1,1,1,1,1,1,1,1,1,1,1,1,1,1,1,1
1,1,1,1,1,1,1,1,1,1,1,1,1,1,1,1,1,1,1,1,1,1,1,1,1,1,1
1,1,1,1,1,1,1,1,1,1,1,1,1,1,1,1,1,1,1,1,1,1,1,1,1,1,1
endlayer

layer
1,1,1,1,1,1,1,1,1,1,1,1,1,1,1,1,1,1,1,1,1,1,1,1,1,1,1
1,1,1,1,1,1,1,1,1,1,1,1,1,1,1,1,1,1,1,1,1,1,1,1,1,1,1
1,1,1,1,1,1,1,1,1,1,1,1,1,1,1,1,1,1,1,1,1,12,13,12,12,1,1
1,1,1,1,1,1,1,1,1,1,1,1,1,1,1,1,1,1,1,12,15,0,0,0,14,1,1
1,1,1,1,1,1,1,1,1,1,1,1,1,1,1,1,1,12,13,0,0,0,0,0,13,1,1
1,1,1,1,1,1,1,1,1,1,1,1,1,1,1,1,13,0,0,0,0,0,0,0,14,1,1
1,1,1,1,1,1,1,1,1,1,1,1,1,1,12,13,0,0,0,0,5,0,0,11,1,1,1
1,1,1,1,1,1,1,1,1,1,1,1,1,13,16,0,0,0,0,0,0,0,0,14,1,1,1
1,1,1,1,1,1,1,1,1,1,1,1,13,16,0,0,0,0,0,0,0,0,13,1,1,1,1
1,1,1,1,1,1,1,1,1,1,1,13,16,0,0,0,0,0,0,0,0,10,14,1,1,1,1
1,1,1,1,1,1,1,1,1,1,13,16,0,0,0,0,0,0,0,0,0,14,1,1,1,1,1
1,1,1,1,1,1,1,1,1,13,16,0,0,0,0,5,0,0,0,0,13,1,1,1,1,1,1
1,1,1,1,1,1,1,1,13,16,0,0,0,0,0,0,0,0,0,16,14,1,1,1,1,1,1
1,1,1,1,1,1,1,13,16,0,0,0,0,0,0,0,0,0,16,13,1,1,1,1,1,1,1
1,1,1,1,1,1,17,16,0,0,0,0,0,0,0,0,0,16,13,1,1,1,1,1,1,1,1
1,1,1,1,1,1,13,0,0,0,0,0,0,0,0,0,16,13,1,1,1,1,1,1,1,1,1
1,1,1,1,1,13,0,0,0,0,5,0,0,0,0,16,13,1,1,1,1,1,1,1,1,1,1
1,1,1,1,17,0,0,0,0,0,0,0,0,0,16,13,1,1,1,1,1,1,1,1,1,1,1
1,1,1,1,13,0,0,0,0,0,0,0,0,16,13,1,1,1,1,1,1,1,1,1,1,1,1
1,1,1,17,0,0,0,0,0,0,0,11,13,18,1,1,1,1,1,1,1,1,1,1,1,1,1
1,1,1,13,0,0,0,0,0,0,13,13,18,1,1,1,1,1,1,1,1,1,1,1,1,1,1
1,1,17,13,0,0,0,0,0,0,13,1,1,1,1,1,1,1,1,1,1,1,1,1,1,1,1
1,1,13,13,0,0,0,0,13,18,1,1,1,1,1,1,1,1,1,1,1,1,1,1,1,1,1
1,1,17,13,13,13,13,18,1,1,1,1,1,1,1,1,1,1,1,1,1,1,1,1,1,1,1
1,1,1,18,13,18,1,1,1,1,1,1,1,1,1,1,1,1,1,1,1,1,1,1,1,1,1
1,1,1,1,1,1,1,1,1,1,1,1,1,1,1,1,1,1,1,1,1,1,1,1,1,1,1
1,1,1,1,1,1,1,1,1,1,1,1,1,1,1,1,1,1,1,1,1,1,1,1,1,1,1
endlayer

layer
1,1,1,1,1,1,1,1,1,1,1,1,1,1,1,1,1,1,1,1,1,1,1,1,1,1,1
1,1,1,1,1,1,1,1,1,1,1,1,1,1,1,1,1,1,1,1,1,1,1,12,12,12,1
1,1,1,1,1,1,1,1,1,1,1,1,1,1,1,1,1,1,1,1,12,19,13,13,13,14,1
1,1,1,1,1,1,1,1,1,1,1,1,1,1,1,1,1,1,12,13,0,0,0,0,13,14,1
1,1,1,1,1,1,1,1,1,1,1,1,1,1,1,20,12,13,0,0,0,0,0,0,13,1,1
1,1,1,1,1,1,1,1,1,1,1,1,1,20,1,13,21,21,21,0,0,0,0,0,10,1,1
1,1,1,1,1,1,1,1,1,1,1,1,1,13,13,21,22,22,21,21,5,0,0,0,14,1,1
1,1,1,1,1,1,1,1,1,1,1,20,13,21,22,22,23,23,21,21,21,0,0,13,1,1,1
1,1,1,1,1,1,1,1,1,1,20,13,21,21,23,23,21,21,21,21,21,24,13,14,1,1,1
1,1,1,1,1,1,1,1,1,25,13,21,21,21,21,21,21,21,21,21,21,24,13,1,1,1,1
1,1,1,1,1,1,1,1,1,13,21,24,26,21,21,21,21,21,21,21,21,16,14,1,1,1,1
1,1,1,1,1,1,1,25,13,21,21,24,26,21,21,5,21,21,21,21,21,14,1,1,1,1,1
1,1,1,1,1,1,1,17,21,21,24,26,21,21,21,21,21,21,21,21,13,27,1,1,1,1,1
1,1,1,1,1,1,17,13,21,21,24,26,21,21,21,21,21,21,21,21,14,1,1,1,1,1,1
1,1,1,1,1,17,13,21,21,21,21,21,21,21,21,21,21,21,21,13,27,1,1,1,1,1,1
1,1,1,1,1,13,0,21,21,21,21,21,21,21,21,21,21,21,13,1,1,1,1,1,1,1,1
1,1,1,1,17,13,0,0,21,21,5,21,21,21,21,21,21,13,27,1,1,1,1,1,1,1,1
1,1,1,1,13,0,0,0,21,21,21,21,21,21,21,21,13,1,1,1,1,1,1,1,1,1,1
1,1,1,17,21,21,21,21,21,21,21,21,21,21,21,13,28,1,1,1,1,1,1,1,1,1,1
1,1,1,13,21,21,21,21,21,0,22,22,16,21,13,1,1,1,1,1,1,1,1,1,1,1,1
1,1,17,21,21,21,21,21,21,21,13,29,13,18,28,1,1,1,1,1,1,1,1,1,1,1,1
1,1,13,21,21,21,21,21,21,21,13,13,18,1,1,1,1,1,1,1,1,1,1,1,1,1,1
1,17,13,21,21,21,21,21,21,13,18,1,1,1,1,1,1,1,1,1,1,1,1,1,1,1,1
1,17,13,21,21,21,21,13,18,1,1,1,1,1,1,1,1,1,1,1,1,1,1,1,1,1,1
1,21,13,13,13,13,18,1,1,1,1,1,1,1,1,1,1,1,1,1,1,1,1,1,1,1,1
1,1,21,18,18,1,1,1,1,1,1,1,1,1,1,1,1,1,1,1,1,1,1,1,1,1,1
1,1,1,1,1,1,1,1,1,1,1,1,1,1,1,1,1,1,1,1,1,1,1,1,1,1,1
endlayer

layer
1,1,1,1,1,1,1,1,1,1,1,1,1,1,1,1,1,1,1,1,1,1,1,12,13,12,14
1,1,1,1,1,1,1,1,1,1,1,1,1,1,1,1,1,1,1,1,1,12,13,13,13,13,14
1,1,1,1,1,1,1,1,1,1,1,1,1,1,1,1,1,1,1,12,13,13,13,13,13,13,13
1,1,1,1,1,1,1,1,1,1,1,1,1,1,1,1,1,16,16,16,16,21,21,21,13,13,14
1,1,1,1,1,1,1,1,1,1,1,1,1,1,1,1,4,16,16,16,16,16,16,21,13,13,1
1,1,1,1,1,1,1,1,1,1,1,1,1,1,1,30,0,0,0,16,16,16,16,21,13,14,1
1,1,1,1,1,1,1,1,1,1,1,1,1,30,30,0,0,0,0,31,5,16,16,16,13,1,1
1,1,1,1,1,1,1,1,1,1,1,1,32,0,0,0,0,0,0,0,31,16,16,16,14,1,1
1,1,1,1,1,1,1,1,1,1,1,0,0,0,0,0,0,0,0,0,0,0,16,16,1,1,1
1,1,1,1,1,1,1,1,1,1,0,0,0,0,0,0,0,0,0,0,0,0,16,16,1,1,1
1,1,1,1,1,1,1,1,1,33,0,0,0,0,0,31,0,0,0,0,0,0,3,1,1,1,1
1,1,1,1,1,1,1,1,30,0,0,0,0,0,0,5,31,0,0,0,0,30,1,1,1,1,1
1,1,1,1,1,1,1,30,0,0,0,0,0,0,0,34,0,0,0,0,30,1,1,1,1,1,1
1,1,1,1,1,1,7,0,0,0,0,0,0,0,0,0,0,0,0,0,30,1,1,1,1,1,1
1,1,1,1,36,13,13,10,0,0,0,0,0,0,0,0,0,0,0,35,1,1,1,1,1,1,1
1,1,1,1,13,13,13,19,0,0,31,31,0,0,0,0,0,0,30,1,1,1,1,1,1,1,1
1,1,1,1,13,13,13,19,0,0,5,31,0,0,0,0,0,30,1,1,1,1,1,1,1,1,1
1,1,1,17,13,13,13,13,13,0,0,0,0,0,0,0,37,1,1,1,1,1,1,1,1,1,1
1,1,17,13,0,0,0,0,38,0,0,0,0,0,0,30,1,1,1,1,1,1,1,1,1,1,1
1,1,13,0,0,0,0,0,0,13,0,0,0,0,30,1,1,1,1,1,1,1,1,1,1,1,1
1,17,39,0,0,0,0,0,0,0,13,29,0,6,1,1,1,1,1,1,1,1,1,1,1,1,1
1,13,0,0,0,0,0,0,0,0,13,13,16,1,1,1,1,1,1,1,1,1,1,1,1,1,1
1,13,0,0,0,0,0,0,0,0,13,14,1,1,1,1,1,1,1,1,1,1,1,1,1,1,1
17,13,21,18,0,0,0,0,0,13,1,1,1,1,1,1,1,1,1,1,1,1,1,1,1,1,1
17,13,21,12,0,0,40,13,18,1,1,1,1,1,1,1,1,1,1,1,1,1,1,1,1,1,1
1,13,13,13,13,18,18,1,1,1,1,1,1,1,1,1,1,1,1,1,1,1,1,1,1,1,1
1,1,18,18,1,1,1,1,1,1,1,1,1,1,1,1,1,1,1,1,1,1,1,1,1,1,1
endlayer

layer
1,1,1,1,1,1,1,1,1,1,1,1,1,1,1,1,1,1,1,1,1,1,1,16,6,4,16
1,1,1,1,1,1,1,1,1,1,1,1,1,1,1,1,1,1,1,1,1,35,30,0,16,16,3
1,1,1,1,1,1,1,1,1,1,1,1,1,1,1,1,1,1,1,33,30,0,0,0,0,16,7
1,1,1,1,1,1,1,1,1,1,1,1,1,1,1,1,1,8,8,0,0,0,0,0,0,0,16
1,1,1,1,1,1,1,1,1,1,1,1,1,1,1,1,8,0,0,0,0,0,0,0,0,30,1
1,1,1,1,1,1,1,1,1,1,1,1,1,1,1,0,0,0,0,0,41,0,0,0,0,32,1
1,1,1,1,1,1,1,1,1,1,1,1,1,0,0,0,0,0,0,31,5,42,0,0,30,1,1
1,1,1,1,1,1,1,1,1,1,1,1,0,0,0,0,0,0,0,0,31,0,0,0,37,1,1
1,1,1,1,1,1,1,1,1,1,1,0,0,0,0,0,0,0,0,0,0,0,0,8,1,1,1
1,1,1,1,1,1,1,1,1,1,0,0,0,0,0,0,0,0,0,0,0,0,0,8,1,1,1
1,1,1,1,1,1,1,1,1,0,0,0,0,0,0,31,0,0,0,0,0,0,8,1,1,1,1
1,1,1,1,1,1,1,1,0,0,0,0,0,0,0,5,31,0,0,0,0,0,1,1,1,1,1
1,1,1,1,1,1,1,0,0,0,0,0,0,0,0,34,0,0,0,0,0,1,1,1,1,1,1
1,1,1,1,1,1,8,0,0,0,0,0,0,0,0,0,0,0,0,0,0,1,1,1,1,1,1
1,1,1,1,36,2,10,0,0,0,0,0,0,0,0,0,0,0,0,0,1,1,1,1,1,1,1
1,1,1,1,2,13,19,0,0,0,31,0,0,0,0,0,0,0,0,1,1,1,1,1,1,1,1
1,1,1,36,13,13,19,0,0,0,5,31,0,0,0,0,0,0,1,1,1,1,1,1,1,1,1
1,1,36,13,13,13,13,13,13,0,0,0,0,0,0,0,0,1,1,1,1,1,1,1,1,1,1
1,1,29,13,0,0,0,0,43,0,0,0,0,0,0,0,1,1,1,1,1,1,1,1,1,1,1
1,1,15,0,0,0,0,0,0,13,0,0,0,0,0,1,1,1,1,1,1,1,1,1,1,1,1
1,10,0,0,0,0,0,0,0,0,13,29,8,8,1,1,1,1,1,1,1,1,1,1,1,1,1
1,13,0,0,0,0,0,0,0,0,13,13,0,1,1,1,1,1,1,1,1,1,1,1,1,1,1
17,0,0,0,0,0,0,0,0,0,13,36,1,1,1,1,1,1,1,1,1,1,1,1,1,1,1
13,45,44,44,0,0,0,0,0,13,36,1,1,1,1,1,1,1,1,1,1,1,1,1,1,1,1
29,45,44,44,0,0,0,11,29,1,1,1,1,1,1,1,1,1,1,1,1,1,1,1,1,1,1
36,13,46,46,46,13,19,1,1,1,1,1,1,1,1,1,1,1,1,1,1,1,1,1,1,1,1
1,36,29,13,18,1,1,1,1,1,1,1,1,1,1,1,1,1,1,1,1,1,1,1,1,1,1
endlayer

layer
1,1,1,1,1,1,1,1,1,1,1,1,1,1,1,1,1,1,1,1,1,1,1,8,8,8,31
1,1,1,1,1,1,1,1,1,1,1,1,1,1,1,1,1,1,1,1,1,0,0,0,0,0,8
1,1,1,1,1,1,1,1,1,1,1,1,1,1,1,1,1,1,1,0,0,0,0,0,0,0,8
1,1,1,1,1,1,1,1,1,1,1,1,1,1,1,1,1,0,0,0,0,0,0,0,0,0,8
1,1,1,1,1,1,1,1,1,1,1,1,1,1,1,1,0,0,0,0,0,0,0,0,0,0,1
1,1,1,1,1,1,1,1,1,1,1,1,1,1,1,0,0,0,0,0,0,0,0,0,0,0,1
1,1,1,1,1,1,1,1,1,1,1,1,1,0,0,0,0,0,0,0,5,27,0,0,0,1,1
1,1,1,1,1,1,1,1,1,1,1,1,0,0,0,0,0,0,0,0,31,0,0,0,0,1,1
1,1,1,1,1,1,1,1,1,1,1,0,0,0,0,0,0,0,0,0,0,0,0,0,1,1,1
1,1,1,1,1,1,1,1,1,1,0,0,0,0,0,0,0,0,0,0,0,0,0,0,1,1,1
1,1,1,1,1,1,1,1,1,0,0,0,0,0,0,0,0,0,0,0,0,0,0,1,1,1,1
1,1,1,1,1,1,1,1,0,0,0,0,0,0,0,5,31,0,0,0,0,0,1,1,1,1,1
1,1,1,1,1,1,1,0,0,0,0,0,0,0,0,34,0,0,0,0,0,1,1,1,1,1,1
1,1,1,1,1,1,0,0,0,0,0,0,0,0,0,0,0,0,0,0,0,1,1,1,1,1,1
1,1,1,1,1,32,0,0,0,0,0,0,0,0,0,0,0,0,0,0,1,1,1,1,1,1,1
1,1,1,1,30,0,0,0,0,0,31,0,0,0,0,0,0,0,0,1,1,1,1,1,1,1,1
1,1,1,30,0,0,0,0,0,0,5,0,0,0,0,0,0,0,1,1,1,1,1,1,1,1,1
1,1,36,13,10,10,13,13,13,0,0,0,0,0,0,0,0,1,1,1,1,1,1,1,1,1,1
1,1,29,13,0,0,0,0,17,0,0,0,0,0,0,0,1,1,1,1,1,1,1,1,1,1,1
1,1,18,0,0,0,0,0,0,13,14,0,0,0,0,1,1,1,1,1,1,1,1,1,1,1,1
1,12,0,0,0,0,0,0,0,0,13,29,0,0,1,1,1,1,1,1,1,1,1,1,1,1,1
36,13,0,0,0,0,0,0,0,0,13,13,0,1,1,1,1,1,1,1,1,1,1,1,1,1,1
29,0,0,0,0,0,0,0,0,0,13,36,1,1,1,1,1,1,1,1,1,1,1,1,1,1,1
13,0,0,0,0,0,0,0,0,13,36,1,1,1,1,1,1,1,1,1,1,1,1,1,1,1,1
29,0,0,0,0,0,0,17,29,36,1,1,1,1,1,1,1,1,1,1,1,1,1,1,1,1,1
36,13,0,0,0,13,14,1,1,1,1,1,1,1,1,1,1,1,1,1,1,1,1,1,1,1,1
1,36,29,13,29,36,1,1,1,1,1,1,1,1,1,1,1,1,1,1,1,1,1,1,1,1,1
endlayer

layer
1,1,1,1,1,1,1,1,1,1,1,1,1,1,1,1,1,1,1,1,1,1,1,0,0,0,47
1,1,1,1,1,1,1,1,1,1,1,1,1,1,1,1,1,1,1,1,1,0,0,0,0,0,47
1,1,1,1,1,1,1,1,1,1,1,1,1,1,1,1,1,1,1,0,0,0,0,0,0,0,0
1,1,1,1,1,1,1,1,1,1,1,1,1,1,1,1,1,0,0,0,0,0,0,0,0,0,0
1,1,1,1,1,1,1,1,1,1,1,1,1,1,1,1,0,0,0,0,0,0,0,0,0,0,1
1,1,1,1,1,1,1,1,1,1,1,1,1,1,1,0,0,0,0,0,0,0,0,0,0,0,1
1,1,1,1,1,1,1,1,1,1,1,1,1,0,0,0,0,0,0,0,5,0,0,0,0,1,1
1,1,1,1,1,1,1,1,1,1,1,1,0,0,0,0,0,0,0,0,0,0,0,0,0,1,1
1,1,1,1,1,1,1,1,1,1,1,0,0,0,0,0,0,0,0,0,0,0,0,0,1,1,1
1,1,1,1,1,1,1,1,1,1,0,0,0,0,0,0,0,0,0,0,0,0,0,0,1,1,1
1,1,1,1,1,1,1,1,1,0,0,0,0,0,0,0,0,0,0,0,0,0,0,1,1,1,1
1,1,1,1,1,1,1,1,0,0,0,0,0,0,0,5,48,0,0,0,0,0,1,1,1,1,1
1,1,1,1,1,1,1,0,0,0,0,0,0,0,0,34,0,0,0,0,0,1,1,1,1,1,1
1,1,1,1,1,1,0,0,0,0,0,0,0,0,0,0,0,0,0,0,0,1,1,1,1,1,1
1,1,1,1,1,0,0,0,0,0,0,0,0,0,0,0,0,0,0,0,1,1,1,1,1,1,1
1,1,1,1,0,0,0,0,0,0,0,0,0,0,0,0,0,0,0,1,1,1,1,1,1,1,1
1,1,1,31,0,0,0,0,0,0,5,0,0,0,0,0,0,0,1,1,1,1,1,1,1,1,1
1,1,1,32,0,0,13,13,13,0,0,0,0,0,0,0,0,1,1,1,1,1,1,1,1,1,1
1,1,49,13,10,10,21,21,13,14,0,0,0,0,0,0,1,1,1,1,1,1,1,1,1,1,1
1,36,13,24,21,21,21,21,21,13,13,36,0,0,0,1,1,1,1,1,1,1,1,1,1,1,1
1,13,0,0,21,21,21,21,21,21,13,49,0,0,1,1,1,1,1,1,1,1,1,1,1,1,1
36,13,0,0,0,21,21,21,21,21,13,13,0,1,1,1,1,1,1,1,1,1,1,1,1,1,1
49,14,0,0,0,0,21,21,21,21,13,1,1,1,1,1,1,1,1,1,1,1,1,1,1,1,1
13,0,0,0,0,0,0,23,21,13,36,1,1,1,1,1,1,1,1,1,1,1,1,1,1,1,1
49,36,0,0,0,0,0,13,49,36,1,1,1,1,1,1,1,1,1,1,1,1,1,1,1,1,1
36,13,36,0,12,13,13,36,1,1,1,1,1,1,1,1,1,1,1,1,1,1,1,1,1,1,1
1,36,49,13,49,36,1,1,1,1,1,1,1,1,1,1,1,1,1,1,1,1,1,1,1,1,1
endlayer

layer
1,1,1,1,1,1,1,1,1,1,1,1,1,1,1,1,1,1,1,1,1,1,1,0,0,0,0
1,1,1,1,1,1,1,1,1,1,1,1,1,1,1,1,1,1,1,1,1,0,0,0,0,47,0
1,1,1,1,1,1,1,1,1,1,1,1,1,1,1,1,1,1,1,0,0,0,0,0,0,47,47
1,1,1,1,1,1,1,1,1,1,1,1,1,1,1,1,1,0,0,0,0,0,0,0,0,0,0
1,1,1,1,1,1,1,1,1,1,1,1,1,1,1,1,0,0,0,0,0,0,0,0,0,0,1
1,1,1,1,1,1,1,1,1,1,1,1,1,1,1,0,0,0,0,0,0,0,0,0,0,0,1
1,1,1,1,1,1,1,1,1,1,1,1,1,1,0,0,0,0,0,0,5,0,0,0,0,1,1
1,1,1,1,1,1,1,1,1,1,1,1,0,0,0,0,0,0,0,0,0,0,0,0,0,1,1
1,1,1,1,1,1,1,1,1,1,1,0,0,0,0,0,0,0,0,0,0,0,0,0,1,1,1
1,1,1,1,1,1,1,1,1,1,0,0,0,0,0,0,0,0,0,0,0,0,0,0,1,1,1
1,1,1,1,1,1,1,1,1,0,0,0,0,0,0,0,0,0,0,0,0,0,0,1,1,1,1
1,1,1,1,1,1,1,1,0,0,0,0,0,0,0,5,0,0,0,0,0,0,1,1,1,1,1
1,1,1,1,1,1,1,0,0,0,0,0,0,0,0,34,0,0,0,0,0,1,1,1,1,1,1
1,1,1,1,1,1,0,0,0,0,0,0,0,0,0,0,0,0,0,0,1,1,1,1,1,1,1
1,1,1,1,1,0,0,0,0,0,0,0,0,0,0,0,0,0,0,0,1,1,1,1,1,1,1
1,1,1,1,0,0,0,0,0,0,0,0,0,0,0,0,0,0,0,1,1,1,1,1,1,1,1
1,1,1,0,0,0,0,0,0,0,5,0,0,0,0,0,0,0,1,1,1,1,1,1,1,1,1
1,1,1,3,0,0,36,36,0,0,0,0,0,0,0,0,0,1,1,1,1,1,1,1,1,1,1
1,1,6,32,0,0,0,0,31,0,0,0,0,0,0,0,1,1,1,1,1,1,1,1,1,1,1
1,1,30,36,0,0,0,0,0,36,36,0,0,0,0,1,1,1,1,1,1,1,1,1,1,1,1
1,6,13,19,0,0,0,0,0,0,0,32,0,0,1,1,1,1,1,1,1,1,1,1,1,1,1
1,2,13,10,19,0,0,0,0,0,0,30,1,1,1,1,1,1,1,1,1,1,1,1,1,1,1
6,13,13,13,10,19,0,0,0,0,30,1,1,1,1,1,1,1,1,1,1,1,1,1,1,1,1
2,13,13,13,13,10,10,36,35,30,1,1,1,1,1,1,1,1,1,1,1,1,1,1,1,1,1
6,24,13,13,13,13,13,30,4,1,1,1,1,1,1,1,1,1,1,1,1,1,1,1,1,1,1
36,13,23,13,13,2,7,1,1,1,1,1,1,1,1,1,1,1,1,1,1,1,1,1,1,1,1
1,36,7,2,7,1,1,1,1,1,1,1,1,1,1,1,1,1,1,1,1,1,1,1,1,1,1
endlayer

layer
1,1,1,1,1,1,1,1,1,1,1,1,1,1,1,1,1,1,1,1,1,1,1,0,0,0,1
1,1,1,1,1,1,1,1,1,1,1,1,1,1,1,1,1,1,1,1,1,0,0,0,0,0,0
1,1,1,1,1,1,1,1,1,1,1,1,1,1,1,1,1,1,1,0,0,0,0,0,47,47,0
1,1,1,1,1,1,1,1,1,1,1,1,1,1,1,1,1,0,0,0,0,0,0,47,47,0,0
1,1,1,1,1,1,1,1,1,1,1,1,1,1,1,1,0,0,0,0,0,0,0,0,0,0,1
1,1,1,1,1,1,1,1,1,1,1,1,1,1,1,0,0,0,0,0,50,0,0,0,0,0,1
1,1,1,1,1,1,1,1,1,1,1,1,1,1,0,0,0,0,0,0,5,0,0,0,0,1,1
1,1,1,1,1,1,1,1,1,1,1,1,1,0,0,0,0,0,0,0,0,0,0,0,0,1,1
1,1,1,1,1,1,1,1,1,1,1,1,0,0,0,0,0,0,0,0,0,0,0,0,1,1,1
1,1,1,1,1,1,1,1,1,1,1,0,0,0,0,0,0,0,0,0,0,0,0,0,1,1,1
1,1,1,1,1,1,1,1,1,1,0,0,0,0,0,0,0,0,0,0,0,0,0,1,1,1,1
1,1,1,1,1,1,1,1,1,0,0,0,0,0,0,5,0,0,0,0,0,0,1,1,1,1,1
1,1,1,1,1,1,1,1,0,0,0,0,0,0,0,34,0,0,0,0,0,1,1,1,1,1,1
1,1,1,1,1,1,1,0,0,0,0,0,0,0,0,0,0,0,0,0,1,1,1,1,1,1,1
1,1,1,1,1,1,0,0,0,0,0,0,0,0,0,0,0,0,0,1,1,1,1,1,1,1,1
1,1,1,1,1,0,0,0,0,0,0,0,0,0,0,0,0,0,1,1,1,1,1,1,1,1,1
1,1,1,0,0,0,0,0,0,0,5,0,0,0,0,0,0,1,1,1,1,1,1,1,1,1,1
1,1,1,0,0,0,0,0,0,0,0,0,0,0,0,0,1,1,1,1,1,1,1,1,1,1,1
1,1,0,3,0,0,0,0,51,0,0,0,0,0,0,1,1,1,1,1,1,1,1,1,1,1,1
1,1,30,36,0,0,0,0,0,0,0,0,0,0,1,1,1,1,1,1,1,1,1,1,1,1,1
1,0,30,0,0,0,0,0,0,0,0,0,0,1,1,1,1,1,1,1,1,1,1,1,1,1,1
1,37,0,0,0,0,0,0,0,0,0,0,1,1,1,1,1,1,1,1,1,1,1,1,1,1,1
0,30,0,0,0,0,0,0,0,0,0,1,1,1,1,1,1,1,1,1,1,1,1,1,1,1,1
30,0,0,0,0,0,0,36,4,0,1,1,1,1,1,1,1,1,1,1,1,1,1,1,1,1,1
32,36,0,0,0,0,30,35,0,1,1,1,1,1,1,1,1,1,1,1,1,1,1,1,1,1,1
1,30,36,0,30,33,0,1,1,1,1,1,1,1,1,1,1,1,1,1,1,1,1,1,1,1,1
1,1,35,30,0,1,1,1,1,1,1,1,1,1,1,1,1,1,1,1,1,1,1,1,1,1,1
endlayer

layer
1,1,1,1,1,1,1,1,1,1,1,1,1,1,1,1,1,1,1,1,1,1,1,1,1,1,1
1,1,1,1,1,1,1,1,1,1,1,1,1,1,1,1,1,1,1,1,1,1,1,0,0,0,1
1,1,1,1,1,1,1,1,1,1,1,1,1,1,1,1,1,1,1,1,1,0,0,0,47,0,1
1,1,1,1,1,1,1,1,1,1,1,1,1,1,1,1,1,1,1,0,0,0,0,47,47,47,1
1,1,1,1,1,1,1,1,1,1,1,1,1,1,1,1,1,0,0,0,0,0,0,47,0,1,1
1,1,1,1,1,1,1,1,1,1,1,1,1,1,1,1,0,0,0,0,0,0,47,0,0,1,1
1,1,1,1,1,1,1,1,1,1,1,1,1,1,1,0,0,0,0,0,5,52,0,0,1,1,1
1,1,1,1,1,1,1,1,1,1,1,1,1,1,0,0,0,0,0,0,0,0,0,0,1,1,1
1,1,1,1,1,1,1,1,1,1,1,1,0,0,0,0,0,0,0,0,0,0,0,1,1,1,1
1,1,1,1,1,1,1,1,1,1,1,0,0,0,0,0,0,0,0,0,0,0,0,1,1,1,1
1,1,1,1,1,1,1,1,1,1,0,0,0,0,0,0,0,0,0,0,0,0,1,1,1,1,1
1,1,1,1,1,1,1,1,1,0,0,0,0,0,0,5,0,0,0,0,0,1,1,1,1,1,1
1,1,1,1,1,1,1,1,0,0,0,0,0,0,0,34,0,0,0,0,1,1,1,1,1,1,1
1,1,1,1,1,1,1,0,0,0,0,0,0,0,0,0,0,0,0,1,1,1,1,1,1,1,1
1,1,1,1,1,1,0,0,0,0,0,0,0,0,0,0,0,0,0,1,1,1,1,1,1,1,1
1,1,1,1,1,0,0,0,0,0,0,0,0,0,0,0,0,0,1,1,1,1,1,1,1,1,1
1,1,1,1,0,0,0,0,0,0,5,0,0,0,0,0,0,1,1,1,1,1,1,1,1,1,1
1,1,1,0,0,0,0,0,0,0,0,0,0,0,0,0,1,1,1,1,1,1,1,1,1,1,1
1,1,0,0,0,0,0,0,0,0,0,0,0,0,0,1,1,1,1,1,1,1,1,1,1,1,1
1,1,0,0,0,0,0,0,0,0,0,0,0,0,1,1,1,1,1,1,1,1,1,1,1,1,1
1,0,0,0,0,0,0,0,0,0,0,0,0,1,1,1,1,1,1,1,1,1,1,1,1,1,1
1,0,0,0,0,0,0,0,0,0,0,0,1,1,1,1,1,1,1,1,1,1,1,1,1,1,1
0,0,0,0,0,0,0,0,0,0,0,1,1,1,1,1,1,1,1,1,1,1,1,1,1,1,1
0,0,0,0,0,0,0,0,0,0,1,1,1,1,1,1,1,1,1,1,1,1,1,1,1,1,1
0,0,0,0,0,0,0,0,0,1,1,1,1,1,1,1,1,1,1,1,1,1,1,1,1,1,1
1,0,0,0,0,0,0,1,1,1,1,1,1,1,1,1,1,1,1,1,1,1,1,1,1,1,1
1,1,0,0,0,1,1,1,1,1,1,1,1,1,1,1,1,1,1,1,1,1,1,1,1,1,1
endlayer

layer
1,1,1,1,1,1,1,1,1,1,1,1,1,1,1,1,1,1,1,1,1,1,1,1,1,1,1
1,1,1,1,1,1,1,1,1,1,1,1,1,1,1,1,1,1,1,1,1,1,1,1,1,1,1
1,1,1,1,1,1,1,1,1,1,1,1,1,1,1,1,1,1,1,1,1,1,1,0,0,1,1
1,1,1,1,1,1,1,1,1,1,1,1,1,1,1,1,1,1,1,1,1,0,0,0,47,1,1
1,1,1,1,1,1,1,1,1,1,1,1,1,1,1,1,1,1,1,0,0,0,47,47,47,1,1
1,1,1,1,1,1,1,1,1,1,1,1,1,1,1,1,1,0,0,0,0,47,47,0,1,1,1
1,1,1,1,1,1,1,1,1,1,1,1,1,1,1,1,0,0,0,0,5,31,0,0,1,1,1
1,1,1,1,1,1,1,1,1,1,1,1,1,1,1,0,0,0,0,0,0,0,0,1,1,1,1
1,1,1,1,1,1,1,1,1,1,1,1,1,1,0,0,0,0,0,0,0,0,1,1,1,1,1
1,1,1,1,1,1,1,1,1,1,1,1,0,0,0,0,0,0,0,0,0,0,1,1,1,1,1
1,1,1,1,1,1,1,1,1,1,1,0,0,0,0,0,0,0,0,0,0,1,1,1,1,1,1
1,1,1,1,1,1,1,1,1,1,0,0,0,0,0,5,0,0,0,0,1,1,1,1,1,1,1
1,1,1,1,1,1,1,1,1,0,0,0,0,0,0,34,0,0,0,1,1,1,1,1,1,1,1
1,1,1,1,1,1,1,1,0,0,0,0,0,0,0,0,0,0,0,1,1,1,1,1,1,1,1
1,1,1,1,1,1,1,0,0,0,0,0,0,0,0,0,0,0,1,1,1,1,1,1,1,1,1
1,1,1,1,1,1,0,0,0,0,0,0,0,0,0,0,0,1,1,1,1,1,1,1,1,1,1
1,1,1,1,1,0,0,0,0,0,5,0,0,0,0,0,1,1,1,1,1,1,1,1,1,1,1
1,1,1,1,0,0,0,0,0,0,0,0,0,0,0,1,1,1,1,1,1,1,1,1,1,1,1
1,1,1,0,0,0,0,0,0,0,0,0,0,0,1,1,1,1,1,1,1,1,1,1,1,1,1
1,1,0,0,0,0,0,0,0,0,0,0,0,1,1,1,1,1,1,1,1,1,1,1,1,1,1
1,0,0,0,0,0,0,0,0,0,0,0,1,1,1,1,1,1,1,1,1,1,1,1,1,1,1
1,0,0,0,0,0,0,0,0,0,0,1,1,1,1,1,1,1,1,1,1,1,1,1,1,1,1
0,0,0,0,0,0,0,0,0,0,1,1,1,1,1,1,1,1,1,1,1,1,1,1,1,1,1
0,0,0,0,0,0,0,0,0,1,1,1,1,1,1,1,1,1,1,1,1,1,1,1,1,1,1
1,0,0,0,0,0,0,0,1,1,1,1,1,1,1,1,1,1,1,1,1,1,1,1,1,1,1
1,0,0,0,0,0,0,1,1,1,1,1,1,1,1,1,1,1,1,1,1,1,1,1,1,1,1
1,1,1,0,0,1,1,1,1,1,1,1,1,1,1,1,1,1,1,1,1,1,1,1,1,1,1
endlayer

layer
1,1,1,1,1,1,1,1,1,1,1,1,1,1,1,1,1,1,1,1,1,1,1,1,1,1,1
1,1,1,1,1,1,1,1,1,1,1,1,1,1,1,1,1,1,1,1,1,1,1,1,1,1,1
1,1,1,1,1,1,1,1,1,1,1,1,1,1,1,1,1,1,1,1,1,1,1,1,1,1,1
1,1,1,1,1,1,1,1,1,1,1,1,1,1,1,1,1,1,1,1,1,1,1,47,1,1,1
1,1,1,1,1,1,1,1,1,1,1,1,1,1,1,1,1,1,1,1,1,0,47,47,1,1,1
1,1,1,1,1,1,1,1,1,1,1,1,1,1,1,1,1,1,1,0,0,47,0,1,1,1,1
1,1,1,1,1,1,1,1,1,1,1,1,47,1,1,1,1,0,0,0,5,31,0,1,1,1,1
1,1,1,1,1,1,1,1,1,1,1,1,1,47,1,1,0,0,0,0,0,0,1,1,1,1,1
1,1,1,1,1,1,1,1,1,1,1,1,1,1,47,0,0,0,0,0,0,1,1,1,1,1,1
1,1,1,1,1,1,1,1,1,1,1,1,1,0,0,47,0,0,0,0,0,1,1,1,1,1,1
1,1,1,1,1,1,1,1,1,1,1,1,0,0,0,0,47,0,0,0,1,1,1,1,1,1,1
1,1,1,1,1,1,1,47,1,1,1,0,0,0,0,5,0,47,0,1,1,1,1,1,1,1,1
1,1,1,1,1,1,1,1,47,1,0,0,0,0,0,34,0,0,47,1,1,1,1,1,1,1,1
1,1,1,1,1,1,1,1,1,47,0,0,0,0,0,0,0,0,1,47,1,1,1,1,1,1,1
1,1,1,1,1,1,1,1,0,0,47,0,0,0,0,0,0,1,1,1,47,1,1,1,1,1,1
1,1,1,1,1,1,1,0,0,0,0,47,0,0,0,0,1,1,1,1,1,1,1,1,1,1,1
1,1,1,1,1,1,0,0,0,0,5,0,47,0,0,1,1,1,1,1,1,1,1,1,1,1,1
1,1,1,1,1,0,0,0,0,0,0,0,0,47,1,1,1,1,1,1,1,1,1,1,1,1,1
1,1,1,1,0,0,0,0,0,0,0,0,0,1,47,1,1,1,1,1,1,1,1,1,1,1,1
1,1,1,0,0,0,0,0,0,0,0,0,1,1,1,47,1,1,1,1,1,1,1,1,1,1,1
1,1,0,0,0,0,0,0,0,0,0,1,1,1,1,1,1,1,1,1,1,1,1,1,1,1,1
1,1,0,0,0,0,0,0,0,0,1,1,1,1,1,1,1,1,1,1,1,1,1,1,1,1,1
1,0,0,0,0,0,0,0,0,1,1,1,1,1,1,1,1,1,1,1,1,1,1,1,1,1,1
1,0,0,0,0,0,0,0,1,1,1,1,1,1,1,1,1,1,1,1,1,1,1,1,1,1,1
1,0,0,0,0,0,0,1,1,1,1,1,1,1,1,1,1,1,1,1,1,1,1,1,1,1,1
1,1,0,0,0,1,1,1,1,1,1,1,1,1,1,1,1,1,1,1,1,1,1,1,1,1,1
1,1,1,1,1,1,1,1,1,1,1,1,1,1,1,1,1,1,1,1,1,1,1,1,1,1,1
endlayer

layer
1,1,1,1,1,1,1,1,1,1,1,1,1,1,1,1,1,1,1,1,1,1,1,1,1,1,1
1,1,1,1,1,1,1,1,1,1,1,1,1,1,1,1,1,1,1,1,1,1,1,1,1,1,1
1,1,1,1,1,1,1,1,1,1,1,1,1,1,1,1,1,1,1,1,1,1,1,1,1,1,1
1,1,1,1,1,1,1,1,1,1,1,1,1,1,1,1,1,1,1,1,1,1,1,1,1,1,1
1,1,1,1,1,1,1,1,1,1,1,1,1,1,1,1,1,1,1,1,1,1,47,47,1,1,1
1,1,1,1,1,1,1,1,1,1,1,1,1,1,1,1,1,1,1,1,1,47,47,1,1,1,1
1,1,1,1,1,1,1,1,1,1,1,47,47,1,1,1,1,1,1,0,5,31,1,1,1,1,1
1,1,1,1,1,1,1,1,1,1,1,1,47,47,1,1,1,1,0,0,0,1,1,1,1,1,1
1,1,1,1,1,1,1,1,1,1,1,1,1,47,47,1,1,0,0,0,1,1,1,1,1,1,1
1,1,1,1,1,1,1,1,1,1,1,1,1,1,47,47,0,0,0,1,1,1,1,1,1,1,1
1,1,1,1,1,1,1,1,1,1,1,1,1,0,0,47,47,0,1,1,1,1,1,1,1,1,1
1,1,1,1,1,1,47,47,1,1,1,1,0,0,0,5,47,47,1,1,1,1,1,1,1,1,1
1,1,1,1,1,1,1,47,47,1,1,0,0,0,0,34,0,47,47,1,1,1,1,1,1,1,1
1,1,1,1,1,1,1,1,47,47,0,0,0,0,0,0,0,1,47,47,1,1,1,1,1,1,1
1,1,1,1,1,1,1,1,1,47,47,0,0,0,0,0,1,1,1,47,47,1,1,1,1,1,1
1,1,1,1,1,1,1,1,0,0,47,47,0,0,0,1,1,1,1,1,47,1,1,1,1,1,1
1,1,1,1,1,1,1,0,0,0,5,47,47,0,1,1,1,1,1,1,1,1,1,1,1,1,1
1,1,1,1,1,1,0,0,0,0,0,0,47,47,1,1,1,1,1,1,1,1,1,1,1,1,1
1,1,1,1,1,0,0,0,0,0,0,0,1,47,47,1,1,1,1,1,1,1,1,1,1,1,1
1,1,1,1,0,0,0,0,0,0,0,1,1,1,47,47,1,1,1,1,1,1,1,1,1,1,1
1,1,1,0,0,0,0,0,0,0,1,1,1,1,1,47,1,1,1,1,1,1,1,1,1,1,1
1,1,1,0,0,0,0,0,0,1,1,1,1,1,1,1,1,1,1,1,1,1,1,1,1,1,1
1,1,0,0,0,0,0,0,1,1,1,1,1,1,1,1,1,1,1,1,1,1,1,1,1,1,1
1,1,0,0,0,0,0,1,1,1,1,1,1,1,1,1,1,1,1,1,1,1,1,1,1,1,1
1,1,0,0,0,1,1,1,1,1,1,1,1,1,1,1,1,1,1,1,1,1,1,1,1,1,1
1,1,1,1,1,1,1,1,1,1,1,1,1,1,1,1,1,1,1,1,1,1,1,1,1,1,1
1,1,1,1,1,1,1,1,1,1,1,1,1,1,1,1,1,1,1,1,1,1,1,1,1,1,1
endlayer

layer
1,1,1,1,1,1,1,1,1,1,1,1,1,1,1,1,1,1,1,1,1,1,1,1,1,1,1
1,1,1,1,1,1,1,1,1,1,1,1,1,1,1,1,1,1,1,1,1,1,1,1,1,1,1
1,1,1,1,1,1,1,1,1,1,1,1,1,1,1,1,1,1,1,1,1,1,1,1,1,1,1
1,1,1,1,1,1,1,1,1,1,1,1,1,1,1,1,1,1,1,1,1,1,1,1,1,1,1
1,1,1,1,1,1,1,1,1,1,1,1,1,1,1,1,1,1,1,1,1,1,1,1,1,1,1
1,1,1,1,1,1,1,1,1,1,1,1,1,1,1,1,1,1,1,1,1,47,47,1,1,1,1
1,1,1,1,1,1,1,1,1,1,1,1,36,1,1,1,1,1,1,1,5,31,1,1,1,1,1
1,1,1,1,1,1,1,1,1,1,1,54,53,36,1,1,1,1,1,1,50,1,1,1,1,1,1
1,1,1,1,1,1,1,1,1,1,1,1,53,53,36,1,1,1,1,1,1,1,1,1,1,1,1
1,1,1,1,1,1,1,1,1,1,1,1,1,53,53,36,1,1,1,1,1,1,1,1,1,1,1
1,1,1,1,1,1,1,1,1,1,1,1,1,36,53,53,36,1,1,1,1,1,1,1,1,1,1
1,1,1,1,1,1,1,36,1,1,1,1,1,36,16,5,53,36,1,1,1,1,1,1,1,1,1
1,1,1,1,1,1,54,53,36,1,1,1,0,0,16,0,53,53,36,1,1,1,1,1,1,1,1
1,1,1,1,1,1,1,53,53,36,1,1,0,0,0,36,36,53,53,36,1,1,1,1,1,1,1
1,1,1,1,1,1,1,1,53,53,36,0,0,0,0,1,1,1,53,53,36,1,1,1,1,1,1
1,1,1,1,1,1,1,1,1,53,53,36,0,0,1,1,1,1,1,55,1,1,1,1,1,1,1
1,1,1,1,1,1,1,1,0,0,5,53,36,1,1,1,1,1,1,1,1,1,1,1,1,1,1
1,1,1,1,1,1,1,0,0,0,0,53,53,36,1,1,1,1,1,1,1,1,1,1,1,1,1
1,1,1,1,1,1,0,0,0,0,0,1,53,53,36,1,1,1,1,1,1,1,1,1,1,1,1
1,1,1,1,1,0,0,0,0,0,1,1,1,53,53,36,1,1,1,1,1,1,1,1,1,1,1
1,1,1,1,0,0,0,0,0,1,1,1,1,1,55,1,1,1,1,1,1,1,1,1,1,1,1
1,1,1,1,0,0,0,0,1,1,1,1,1,1,1,1,1,1,1,1,1,1,1,1,1,1,1
1,1,1,0,0,0,0,1,1,1,1,1,1,1,1,1,1,1,1,1,1,1,1,1,1,1,1
1,1,1,0,0,1,1,1,1,1,1,1,1,1,1,1,1,1,1,1,1,1,1,1,1,1,1
1,1,1,1,1,1,1,1,1,1,1,1,1,1,1,1,1,1,1,1,1,1,1,1,1,1,1
1,1,1,1,1,1,1,1,1,1,1,1,1,1,1,1,1,1,1,1,1,1,1,1,1,1,1
1,1,1,1,1,1,1,1,1,1,1,1,1,1,1,1,1,1,1,1,1,1,1,1,1,1,1
endlayer

layer
1,1,1,1,1,1,1,1,1,1,1,1,1,1,1,1,1,1,1,1,1,1,1,1,1,1,1
1,1,1,1,1,1,1,1,1,1,1,1,1,1,1,1,1,1,1,1,1,1,1,1,1,1,1
1,1,1,1,1,1,1,1,1,1,1,1,1,1,1,1,1,1,1,1,1,1,1,1,1,1,1
1,1,1,1,1,1,1,1,1,1,1,1,1,1,1,1,1,1,1,1,1,1,1,1,1,1,1
1,1,1,1,1,1,1,1,1,1,1,1,1,1,1,1,1,1,1,1,1,1,1,1,1,1,1
1,1,1,1,1,1,1,1,1,1,1,1,1,1,1,1,1,1,1,1,1,47,1,1,1,1,1
1,1,1,1,1,1,1,1,1,1,1,1,1,1,1,1,1,1,1,48,5,31,1,1,1,1,1
1,1,1,1,1,1,1,1,1,1,1,1,1,1,1,1,1,1,1,1,1,1,1,1,1,1,1
1,1,1,1,1,1,1,1,1,1,1,1,1,1,1,1,1,1,1,1,1,1,1,1,1,1,1
1,1,1,1,1,1,1,1,1,1,1,1,1,1,36,36,1,1,1,1,1,1,1,1,1,1,1
1,1,1,1,1,1,1,1,1,1,1,1,1,36,0,0,0,1,1,1,1,1,1,1,1,1,1
1,1,1,1,1,1,1,1,1,1,1,1,1,36,0,5,0,36,1,1,1,1,1,1,1,1,1
1,1,1,1,1,1,1,1,1,1,1,1,1,36,0,0,0,36,1,1,1,1,1,1,1,1,1
1,1,1,1,1,1,1,1,1,1,1,1,1,1,36,36,36,1,1,1,1,1,1,1,1,1,1
1,1,1,1,1,1,1,1,1,1,1,1,1,1,1,1,1,1,1,1,1,1,1,1,1,1,1
1,1,1,1,1,1,1,1,1,1,1,1,1,1,1,1,1,1,1,1,1,1,1,1,1,1,1
1,1,1,1,1,1,1,1,1,48,5,1,1,1,1,1,1,1,1,1,1,1,1,1,1,1,1
1,1,1,1,1,1,1,1,1,1,1,1,1,1,1,1,1,1,1,1,1,1,1,1,1,1,1
1,1,1,1,1,1,1,1,1,1,1,1,1,1,1,1,1,1,1,1,1,1,1,1,1,1,1
1,1,1,1,1,1,1,1,1,1,1,1,1,1,1,1,1,1,1,1,1,1,1,1,1,1,1
1,1,1,1,1,1,1,1,1,1,1,1,1,1,1,1,1,1,1,1,1,1,1,1,1,1,1
1,1,1,1,1,1,1,1,1,1,1,1,1,1,1,1,1,1,1,1,1,1,1,1,1,1,1
1,1,1,1,1,1,1,1,1,1,1,1,1,1,1,1,1,1,1,1,1,1,1,1,1,1,1
1,1,1,1,1,1,1,1,1,1,1,1,1,1,1,1,1,1,1,1,1,1,1,1,1,1,1
1,1,1,1,1,1,1,1,1,1,1,1,1,1,1,1,1,1,1,1,1,1,1,1,1,1,1
1,1,1,1,1,1,1,1,1,1,1,1,1,1,1,1,1,1,1,1,1,1,1,1,1,1,1
1,1,1,1,1,1,1,1,1,1,1,1,1,1,1,1,1,1,1,1,1,1,1,1,1,1,1
endlayer

layer
1,1,1,1,1,1,1,1,1,1,1,1,1,1,1,1,1,1,1,1,1,1,1,1,1,1,1
1,1,1,1,1,1,1,1,1,1,1,1,1,1,1,1,1,1,1,1,1,1,1,1,1,1,1
1,1,1,1,1,1,1,1,1,1,1,1,1,1,1,1,1,1,1,1,1,1,1,1,1,1,1
1,1,1,1,1,1,1,1,1,1,1,1,1,1,1,1,1,1,1,1,1,1,1,1,1,1,1
1,1,1,1,1,1,1,1,1,1,1,1,1,1,1,1,1,1,1,1,1,1,1,1,1,1,1
1,1,1,1,1,1,1,1,1,1,1,1,1,1,1,1,1,1,1,1,1,1,1,1,1,1,1
1,1,1,1,1,1,1,1,1,1,1,1,1,1,1,1,1,1,1,1,5,1,1,1,1,1,1
1,1,1,1,1,1,1,1,1,1,1,1,1,1,1,1,1,1,1,1,1,1,1,1,1,1,1
1,1,1,1,1,1,1,1,1,1,1,1,1,1,1,1,1,1,1,1,1,1,1,1,1,1,1
1,1,1,1,1,1,1,1,1,1,1,1,1,1,1,1,1,1,1,1,1,1,1,1,1,1,1
1,1,1,1,1,1,1,1,1,1,1,1,1,1,0,0,0,1,1,1,1,1,1,1,1,1,1
1,1,1,1,1,1,1,1,1,1,1,1,1,1,0,5,0,1,1,1,1,1,1,1,1,1,1
1,1,1,1,1,1,1,1,1,1,1,1,1,1,0,0,0,1,1,1,1,1,1,1,1,1,1
1,1,1,1,1,1,1,1,1,1,1,1,1,1,1,1,1,1,1,1,1,1,1,1,1,1,1
1,1,1,1,1,1,1,1,1,1,1,1,1,1,1,1,1,1,1,1,1,1,1,1,1,1,1
1,1,1,1,1,1,1,1,1,1,1,1,1,1,1,1,1,1,1,1,1,1,1,1,1,1,1
1,1,1,1,1,1,1,1,1,1,5,1,1,1,1,1,1,1,1,1,1,1,1,1,1,1,1
1,1,1,1,1,1,1,1,1,1,56,1,1,1,1,1,1,1,1,1,1,1,1,1,1,1,1
1,1,1,1,1,1,1,1,1,1,1,1,1,1,1,1,1,1,1,1,1,1,1,1,1,1,1
1,1,1,1,1,1,1,1,1,1,1,1,1,1,1,1,1,1,1,1,1,1,1,1,1,1,1
1,1,1,1,1,1,1,1,1,1,1,1,1,1,1,1,1,1,1,1,1,1,1,1,1,1,1
1,1,1,1,1,1,1,1,1,1,1,1,1,1,1,1,1,1,1,1,1,1,1,1,1,1,1
1,1,1,1,1,1,1,1,1,1,1,1,1,1,1,1,1,1,1,1,1,1,1,1,1,1,1
1,1,1,1,1,1,1,1,1,1,1,1,1,1,1,1,1,1,1,1,1,1,1,1,1,1,1
1,1,1,1,1,1,1,1,1,1,1,1,1,1,1,1,1,1,1,1,1,1,1,1,1,1,1
1,1,1,1,1,1,1,1,1,1,1,1,1,1,1,1,1,1,1,1,1,1,1,1,1,1,1
1,1,1,1,1,1,1,1,1,1,1,1,1,1,1,1,1,1,1,1,1,1,1,1,1,1,1
endlayer

layer
1,1,1,1,1,1,1,1,1,1,1,1,1,1,1,1,1,1,1,1,1,1,1,1,1,1,1
1,1,1,1,1,1,1,1,1,1,1,1,1,1,1,1,1,1,1,1,1,1,1,1,1,1,1
1,1,1,1,1,1,1,1,1,1,1,1,1,1,1,1,1,1,1,1,1,1,1,1,1,1,1
1,1,1,1,1,1,1,1,1,1,1,1,1,1,1,1,1,1,1,1,1,1,1,1,1,1,1
1,1,1,1,1,1,1,1,1,1,1,1,1,1,1,1,1,1,1,1,1,1,1,1,1,1,1
1,1,1,1,1,1,1,1,1,1,1,1,1,1,1,1,1,1,1,1,1,1,1,1,1,1,1
1,1,1,1,1,1,1,1,1,1,1,1,1,1,1,1,1,1,1,1,1,1,1,1,1,1,1
1,1,1,1,1,1,1,1,1,1,1,1,1,1,1,1,1,1,1,1,1,1,1,1,1,1,1
1,1,1,1,1,1,1,1,1,1,1,1,1,1,1,1,1,1,1,1,1,1,1,1,1,1,1
1,1,1,1,1,1,1,1,1,1,1,1,1,1,1,1,1,1,1,1,1,1,1,1,1,1,1
1,1,1,1,1,1,1,1,1,1,1,1,1,1,0,0,0,1,1,1,1,1,1,1,1,1,1
1,1,1,1,1,1,1,1,1,1,1,1,1,1,0,5,0,1,1,1,1,1,1,1,1,1,1
1,1,1,1,1,1,1,1,1,1,1,1,1,1,0,0,0,1,1,1,1,1,1,1,1,1,1
1,1,1,1,1,1,1,1,1,1,1,1,1,1,1,1,1,1,1,1,1,1,1,1,1,1,1
1,1,1,1,1,1,1,1,1,1,1,1,1,1,1,1,1,1,1,1,1,1,1,1,1,1,1
1,1,1,1,1,1,1,1,1,1,1,1,1,1,1,1,1,1,1,1,1,1,1,1,1,1,1
1,1,1,1,1,1,1,1,1,1,5,1,1,1,1,1,1,1,1,1,1,1,1,1,1,1,1
1,1,1,1,1,1,1,1,1,1,1,1,1,1,1,1,1,1,1,1,1,1,1,1,1,1,1
1,1,1,1,1,1,1,1,1,1,1,1,1,1,1,1,1,1,1,1,1,1,1,1,1,1,1
1,1,1,1,1,1,1,1,1,1,1,1,1,1,1,1,1,1,1,1,1,1,1,1,1,1,1
1,1,1,1,1,1,1,1,1,1,1,1,1,1,1,1,1,1,1,1,1,1,1,1,1,1,1
1,1,1,1,1,1,1,1,1,1,1,1,1,1,1,1,1,1,1,1,1,1,1,1,1,1,1
1,1,1,1,1,1,1,1,1,1,1,1,1,1,1,1,1,1,1,1,1,1,1,1,1,1,1
1,1,1,1,1,1,1,1,1,1,1,1,1,1,1,1,1,1,1,1,1,1,1,1,1,1,1
1,1,1,1,1,1,1,1,1,1,1,1,1,1,1,1,1,1,1,1,1,1,1,1,1,1,1
1,1,1,1,1,1,1,1,1,1,1,1,1,1,1,1,1,1,1,1,1,1,1,1,1,1,1
1,1,1,1,1,1,1,1,1,1,1,1,1,1,1,1,1,1,1,1,1,1,1,1,1,1,1
endlayer

