
# Created by Ruins mod version 16.7 Ingame Parser
# authoring Player: lafuller

weight=1
embed_into_distance=8
acceptable_target_blocks=
unacceptable_target_blocks=flowing_water,water,flowing_lava,lava,ice,bedrock,netherrack,nether_brick,nether_brick_fence,soul_sand,quartz_ore,end_stone,obsidian,iron_bars,cloud,flesh,ash_block,slime_grass,slime_congealed,slime_dirt
dimensions=58,14,14
allowable_overhang=0
max_leveling=8
leveling_buffer=-1
preserve_water=0
preserve_lava=0
preventRotation=1

rule1=0,100,preserveBlock
rule2=0,100,stonebrick-0,stonebrick-0,stonebrick-1,stonebrick-1,stonebrick-2,stonebrick-2,stone-5,stone-6,cobblestone
rule3=0,100,minecraft:stone_brick_stairs-6
rule4=0,100,minecraft:stone_brick_stairs-0
rule5=0,100,minecraft:stone_brick_stairs-4
rule6=0,100,minecraft:stone_brick_stairs-5
rule7=0,100,minecraft:stone_brick_stairs-1
rule8=0,100,minecraft:stone_brick_stairs-7
rule9=0,100,minecraft:stone_brick_stairs-2
rule10=0,100,minecraft:stone_brick_stairs-3
rule11=0,100,CommandBlock:RUINSTRIGGER /testruin Gilly/GillyCatacombs ~0 ~0 ~0 0:@
rule12=0,100,minecraft:iron_bars-0
rule13=0,100,minecraft:stone_slab-13
rule14=0,100,minecraft:planks-1
rule15=0,100,minecraft:stone_slab-5
rule16=0,100,minecraft:spruce_stairs-6
rule17=0,100,minecraft:spruce_stairs-3
rule18=0,100,minecraft:spruce_stairs-2
rule19=0,100,minecraft:spruce_stairs-7
rule20=0,100,minecraft:spruce_stairs-0
rule21=0,100,minecraft:spruce_stairs-4
rule22=0,100,minecraft:spruce_stairs-5
rule23=0,100,minecraft:spruce_stairs-1

layer
2,2,2,2,2,2,2,2,2,2,2,2,2,9
2,2,2,2,2,2,2,2,2,2,2,2,2,2
2,2,2,2,2,2,2,2,2,2,2,2,2,2
2,2,2,3,0,0,0,0,0,0,0,0,2,2
2,2,2,3,0,0,0,0,0,0,0,0,2,2
2,2,2,5,5,0,0,0,0,0,4,4,2,2
2,2,2,2,2,0,0,0,0,0,2,2,2,2
2,2,2,2,2,0,0,0,0,0,2,2,2,2
2,2,2,2,2,0,0,0,0,0,2,2,2,2
2,2,2,7,7,0,0,0,0,0,6,6,2,2
2,2,2,0,0,0,0,0,0,0,0,8,2,2
2,2,2,0,0,0,0,0,0,0,0,8,2,2
2,2,2,2,2,2,2,2,2,2,2,2,2,2
2,2,2,2,2,2,2,2,2,2,2,2,2,2
endlayer

layer
2,2,2,2,2,2,2,2,2,2,2,2,9,1
2,2,2,2,2,2,2,2,2,2,2,2,2,2
2,2,2,2,2,2,2,2,2,2,2,2,2,2
2,2,2,9,3,0,0,0,0,0,0,0,2,2
2,2,2,9,5,0,0,0,0,0,0,0,2,2
2,2,2,2,2,0,0,0,0,0,0,0,2,2
2,2,2,2,2,0,0,0,0,0,4,4,2,2
2,2,2,2,2,0,0,0,0,0,2,2,2,2
2,2,2,7,7,0,0,0,0,0,2,2,2,2
2,2,2,0,0,0,0,0,0,0,2,2,2,2
2,2,2,0,0,0,0,0,0,0,6,2,2,2
2,2,2,0,0,0,0,0,0,0,8,2,2,2
10,2,2,2,2,2,2,2,2,2,2,2,2,2
10,2,2,2,2,2,2,2,2,2,2,2,2,2
endlayer

layer
2,2,2,2,2,2,2,2,2,2,2,9,1,1
2,2,2,2,2,2,2,2,2,2,2,2,2,2
2,2,2,2,2,2,2,2,2,2,2,2,2,2
2,2,2,2,2,3,0,0,0,0,0,0,2,2
2,2,2,2,2,3,0,0,0,0,0,0,2,2
2,2,2,2,2,0,0,0,0,0,0,0,2,2
2,2,2,2,2,0,0,0,0,0,0,0,2,2
2,2,2,7,7,0,0,0,0,0,4,4,2,2
2,2,2,0,0,0,0,0,0,0,2,2,2,2
2,2,2,0,0,0,0,0,0,0,2,2,2,2
2,2,2,0,0,0,0,0,0,8,2,2,2,2
7,2,2,0,0,0,0,0,0,8,2,2,2,2
1,10,2,2,2,2,2,2,2,2,2,2,2,7
1,10,2,2,2,2,2,2,2,2,2,2,9,1
endlayer

layer
2,2,2,2,2,2,2,2,2,2,9,1,1,1
2,2,2,2,2,2,2,2,2,2,2,2,2,2
2,2,2,2,2,2,2,2,2,2,2,2,2,2
2,2,2,2,2,2,3,0,0,0,0,0,2,2
2,2,2,2,2,2,3,0,0,0,0,0,2,2
2,2,2,2,2,0,0,0,0,0,0,0,2,2
2,2,2,7,7,0,0,0,0,0,0,0,2,2
2,2,2,0,0,0,0,11,0,0,0,0,2,2
2,2,2,0,0,0,0,0,0,0,4,4,2,2
2,2,2,0,0,0,0,0,0,0,2,2,2,2
7,2,2,0,0,0,0,0,8,2,2,2,2,2
1,2,2,0,0,0,0,0,8,2,2,2,2,7
1,1,10,2,2,2,2,2,2,2,2,2,2,1
1,1,10,2,2,2,2,2,2,2,2,9,1,1
endlayer

layer
2,2,2,2,2,2,2,2,2,9,1,1,1,1
2,2,2,2,2,2,2,2,2,2,2,2,2,2
2,2,2,2,2,2,2,2,2,2,2,2,2,2
2,2,2,2,2,2,2,2,2,3,0,0,2,2
2,2,2,2,2,2,2,2,2,3,0,0,2,2
2,2,2,7,7,10,2,2,2,5,0,0,2,2
2,2,2,0,0,10,2,2,2,7,0,0,2,2
2,2,2,0,0,10,2,12,2,9,0,0,2,2
2,2,2,0,0,4,2,2,2,9,0,0,2,2
7,2,2,0,0,6,2,2,2,9,4,4,2,2
1,2,2,0,0,8,2,2,2,2,2,2,9,7
1,2,2,5,5,8,2,2,2,2,2,2,9,1
1,1,1,10,2,2,2,2,2,2,7,7,9,1
1,1,1,10,2,2,2,2,7,7,9,1,1,1
endlayer

layer
4,10,2,2,2,2,2,2,9,1,1,1,1,1
2,2,2,2,2,2,2,2,2,1,1,1,10,4
2,2,2,2,2,2,2,2,2,2,2,2,2,2
2,2,2,2,2,2,2,2,2,2,6,6,2,2
2,2,2,2,0,0,0,0,0,0,0,0,2,2
2,2,2,0,0,0,0,0,0,0,0,0,2,2
2,2,2,0,0,0,0,0,0,0,0,0,2,2
2,2,2,0,0,0,0,0,0,0,0,0,2,2
7,2,2,0,0,0,0,0,0,0,0,0,2,2
1,2,2,0,0,0,0,0,0,0,0,0,10,7
1,2,2,0,0,0,0,0,0,0,0,1,1,1
1,2,2,2,2,2,2,2,0,0,2,1,1,1
1,1,1,1,10,2,2,9,1,1,1,1,1,1
1,1,1,1,10,2,2,9,1,1,1,1,1,1
endlayer

layer
1,1,10,2,2,2,2,9,1,1,1,1,1,1
4,4,2,2,2,2,2,2,2,1,1,1,1,1
2,2,2,2,2,2,2,2,2,2,2,2,4,4
2,2,2,2,2,2,2,2,2,2,2,2,2,2
2,2,2,2,0,0,0,0,0,0,6,6,2,2
2,2,2,0,0,0,0,0,0,0,0,0,2,2
2,2,2,0,0,0,0,0,0,0,0,0,2,2
7,2,2,0,0,0,0,0,0,0,0,0,2,2
1,2,2,0,0,0,0,0,0,0,0,0,2,7
1,2,2,0,0,0,0,0,0,0,0,0,1,1
1,2,2,0,0,0,0,0,0,0,0,1,1,1
1,2,2,2,2,2,2,2,0,0,2,1,1,1
1,1,1,1,1,10,9,1,1,1,1,1,1,1
1,1,1,1,1,10,9,1,1,1,1,1,1,1
endlayer

layer
1,1,1,1,1,1,1,1,1,1,1,1,1,1
1,1,4,4,2,2,2,2,2,1,1,1,1,1
4,4,2,2,2,2,2,2,2,2,2,2,1,1
2,2,2,2,2,2,2,2,2,2,2,2,4,1
2,2,2,2,0,0,0,0,0,0,2,2,9,1
2,2,2,13,0,0,0,0,0,0,6,6,2,1
7,2,2,13,0,0,0,0,0,0,0,13,2,1
1,2,2,13,0,0,0,0,0,0,0,13,9,1
1,2,2,13,0,0,0,0,0,0,0,13,9,1
1,2,2,13,0,0,0,0,0,0,0,1,1,1
1,2,2,13,0,0,0,0,0,0,0,1,1,1
1,2,2,2,2,7,7,2,0,0,2,1,1,1
1,1,1,1,1,1,1,1,1,1,1,1,1,1
1,1,1,1,1,1,1,1,1,1,1,1,1,1
endlayer

layer
1,1,1,1,1,1,1,1,1,1,1,1,1,1
1,1,1,1,10,2,2,2,2,1,1,1,1,1
1,1,4,4,2,2,2,2,2,2,2,2,1,1
1,10,2,2,2,2,2,2,2,2,2,9,1,1
1,10,2,2,2,2,2,2,2,2,2,9,1,1
1,2,2,2,2,13,13,13,13,13,2,2,2,1
1,2,2,2,2,13,0,0,0,13,2,2,2,1
1,2,2,2,2,13,0,0,0,13,2,9,1,1
1,2,2,2,2,13,0,0,0,13,2,9,1,1
1,10,2,2,2,13,13,13,13,13,3,1,1,1
1,7,2,2,2,7,7,2,2,2,3,1,1,1
1,1,7,2,2,1,1,2,6,6,2,1,1,1
1,1,1,1,1,1,1,1,1,1,1,1,1,1
1,1,1,1,1,1,1,1,1,1,1,1,1,1
endlayer

layer
1,1,1,1,1,1,1,1,1,1,1,1,1,1
1,1,1,1,1,10,4,4,9,1,1,1,1,1
1,1,1,1,2,2,2,2,4,4,2,2,1,1
1,1,4,4,2,2,2,2,2,2,9,1,1,1
1,1,10,2,2,2,2,2,2,2,9,1,1,1
1,4,2,2,2,2,2,2,2,2,2,2,2,1
1,10,2,2,2,2,2,2,2,2,2,2,2,1
1,10,2,2,2,2,2,12,2,2,9,1,1,1
1,10,2,2,2,2,2,2,2,2,9,1,1,1
1,1,10,2,2,7,7,2,2,2,2,1,1,1
1,1,7,2,2,1,1,2,2,2,9,1,1,1
1,1,1,7,2,1,1,2,7,7,2,1,1,1
1,1,1,1,1,1,1,1,1,1,1,1,1,1
1,1,1,1,1,1,1,1,1,1,1,1,1,1
endlayer

layer
1,1,1,1,1,1,1,1,1,1,1,1,1,1
1,1,1,1,1,1,1,1,1,1,1,1,1,1
1,1,1,1,2,2,2,9,1,1,1,1,1,1
1,1,1,1,2,6,2,2,9,1,1,1,1,1
1,1,1,1,1,1,7,10,2,1,1,1,1,1
1,1,2,2,1,1,1,1,1,1,1,14,14,1
1,1,2,3,1,1,1,1,1,1,1,14,14,1
1,1,2,2,9,1,1,1,1,1,1,1,1,1
1,1,7,2,4,1,1,1,1,1,1,1,1,1
1,1,1,7,2,1,1,1,1,1,1,1,1,1
1,1,1,1,1,1,1,1,1,1,1,1,1,1
1,1,1,1,1,1,1,1,1,1,1,1,1,1
1,1,1,1,1,1,1,1,1,1,1,1,1,1
1,1,1,1,1,1,1,1,1,1,1,1,1,1
endlayer

layer
1,1,1,1,1,1,1,1,1,1,1,1,1,1
1,1,1,1,1,1,1,1,1,1,1,1,1,1
1,1,1,1,2,2,15,1,1,1,1,1,1,1
1,1,1,1,2,2,9,1,1,1,1,1,1,1
1,1,1,1,1,1,1,1,1,1,1,1,1,1
1,1,2,2,1,1,1,1,1,1,1,17,16,1
1,1,2,2,1,1,1,1,1,1,1,19,18,1
1,1,15,7,1,1,1,1,1,1,1,1,1,1
1,1,1,1,1,1,1,1,1,1,1,1,1,1
1,1,1,1,1,1,1,1,1,1,1,1,1,1
1,1,1,1,1,1,1,1,1,1,1,1,1,1
1,1,1,1,1,1,1,1,1,1,1,1,1,1
1,1,1,1,1,1,1,1,1,1,1,1,1,1
1,1,1,1,1,1,1,1,1,1,1,1,1,1
endlayer

layer
1,1,1,1,1,1,1,1,1,1,1,1,1,1
1,1,1,1,1,1,1,1,1,1,1,1,1,1
1,1,1,1,2,2,1,1,1,1,1,1,1,1
1,1,1,1,2,2,1,1,1,1,1,1,1,1
1,1,1,1,1,1,1,1,1,1,1,1,1,1
1,1,2,2,1,1,1,1,1,1,1,21,20,1
1,1,2,2,1,1,1,1,1,1,1,23,22,1
1,1,1,1,1,1,1,1,1,1,1,1,1,1
1,1,1,1,1,1,1,1,1,1,1,1,1,1
1,1,1,1,1,1,1,1,1,1,1,1,1,1
1,1,1,1,1,1,1,1,1,1,1,1,1,1
1,1,1,1,1,1,1,1,1,1,1,1,1,1
1,1,1,1,1,1,1,1,1,1,1,1,1,1
1,1,1,1,1,1,1,1,1,1,1,1,1,1
endlayer

layer
1,1,1,1,1,1,1,1,1,1,1,1,1,1
1,1,1,1,1,1,1,1,1,1,1,1,1,1
1,1,1,1,2,2,1,1,1,1,1,1,1,1
1,1,1,1,2,2,1,1,1,1,1,1,1,1
1,1,1,1,1,1,1,1,1,1,1,1,1,1
1,1,2,2,1,1,1,1,1,1,1,17,16,1
1,1,2,2,1,1,1,1,1,1,1,19,18,1
1,1,1,1,1,1,1,1,1,1,1,1,1,1
1,1,1,1,1,1,1,1,1,1,1,1,1,1
1,1,1,1,1,1,1,1,1,1,1,1,1,1
1,1,1,1,1,1,1,1,1,1,1,1,1,1
1,1,1,1,1,1,1,1,1,1,1,1,1,1
1,1,1,1,1,1,1,1,1,1,1,1,1,1
1,1,1,1,1,1,1,1,1,1,1,1,1,1
endlayer

layer
1,1,1,1,1,1,1,1,1,1,1,1,1,1
1,1,1,1,1,1,1,1,1,1,1,1,1,1
1,1,1,1,2,2,1,1,1,1,1,1,1,1
1,1,1,1,2,2,1,1,1,1,1,1,1,1
1,1,1,1,1,1,1,1,1,1,1,1,1,1
1,1,2,2,1,1,1,1,1,1,1,21,20,1
1,1,2,2,1,1,1,1,1,1,1,23,22,1
1,1,1,1,1,1,1,1,1,1,1,1,1,1
1,1,1,1,1,1,1,1,1,1,1,1,1,1
1,1,1,1,1,1,1,1,1,1,1,1,1,1
1,1,1,1,1,1,1,1,1,1,1,1,1,1
1,1,1,1,1,1,1,1,1,1,1,1,1,1
1,1,1,1,1,1,1,1,1,1,1,1,1,1
1,1,1,1,1,1,1,1,1,1,1,1,1,1
endlayer

layer
1,1,1,1,1,1,1,1,1,1,1,1,1,1
1,1,1,1,1,1,1,1,1,1,1,1,1,1
1,1,1,1,2,2,1,1,1,1,1,1,1,1
1,1,1,1,2,2,1,1,1,1,1,1,1,1
1,1,1,1,1,1,1,1,1,1,1,1,1,1
1,1,2,2,1,1,1,1,1,1,1,17,16,1
1,1,2,2,1,1,1,1,1,1,1,19,18,1
1,1,1,1,1,1,1,1,1,1,1,1,1,1
1,1,1,1,1,1,1,1,1,1,1,1,1,1
1,1,1,1,1,1,1,1,1,1,1,1,1,1
1,1,1,1,1,1,1,1,1,1,1,1,1,1
1,1,1,1,1,1,1,1,1,1,1,1,1,1
1,1,1,1,1,1,1,1,1,1,1,1,1,1
1,1,1,1,1,1,1,1,1,1,1,1,1,1
endlayer

layer
1,1,1,1,1,1,1,1,1,1,1,1,1,1
1,1,1,1,1,1,1,1,1,1,1,1,1,1
1,1,1,1,2,2,1,1,1,1,1,1,1,1
1,1,1,1,2,2,3,1,1,1,1,1,1,1
1,1,1,1,1,1,1,1,1,1,1,1,1,1
1,1,2,2,1,1,1,1,1,1,1,21,20,1
1,1,2,2,3,1,1,1,1,1,1,23,22,1
1,1,1,1,1,1,1,1,1,1,1,1,1,1
1,1,1,1,1,1,1,1,1,1,1,1,1,1
1,1,1,1,1,1,1,1,1,1,1,1,1,1
1,1,1,1,1,1,1,1,1,1,1,1,1,1
1,1,1,1,1,1,1,1,1,1,1,1,1,1
1,1,1,1,1,1,1,1,1,1,1,1,1,1
1,1,1,1,1,1,1,1,1,1,1,1,1,1
endlayer

layer
1,1,1,1,1,1,1,1,1,1,1,1,1,1
1,1,1,1,1,1,1,1,1,1,1,1,1,1
1,1,1,1,2,2,2,1,1,1,1,1,1,1
1,1,1,1,2,2,2,1,1,1,1,1,1,1
1,1,1,1,1,1,1,1,1,1,1,1,1,1
1,1,2,2,5,1,1,1,1,1,1,17,16,1
1,1,2,2,2,1,1,1,1,1,1,19,18,1
1,1,1,1,1,1,1,1,1,1,1,1,1,1
1,1,1,1,1,1,1,1,1,1,1,1,1,1
1,1,1,1,1,1,1,1,1,1,1,1,1,1
1,1,1,1,1,1,1,1,1,1,1,1,1,1
1,1,1,1,1,1,1,1,1,1,1,1,1,1
1,1,1,1,1,1,1,1,1,1,1,1,1,1
1,1,1,1,1,1,1,1,1,1,1,1,1,1
endlayer

layer
1,1,1,1,1,1,1,1,1,1,1,1,1,1
1,1,1,1,1,1,1,1,1,1,1,1,1,1
1,1,1,1,2,2,2,1,1,1,1,1,1,1
1,1,1,1,2,2,2,1,1,1,1,1,1,1
1,1,1,1,1,6,1,1,1,1,1,1,1,1
1,1,2,2,2,1,1,1,1,1,1,21,20,1
1,1,2,2,2,1,1,1,1,1,1,23,22,1
1,1,1,1,1,1,1,1,1,1,1,1,1,1
1,1,1,1,1,1,1,1,1,1,1,1,1,1
1,1,1,1,1,1,1,1,1,1,1,1,1,1
1,1,1,1,1,1,1,1,1,1,1,1,1,1
1,1,1,1,1,1,1,1,1,1,1,1,1,1
1,1,1,1,1,1,1,1,1,1,1,1,1,1
1,1,1,1,1,1,1,1,1,1,1,1,1,1
endlayer

layer
1,1,1,1,1,1,1,1,1,1,1,1,1,1
1,1,1,1,1,1,1,1,1,1,1,1,1,1
1,1,1,1,2,2,2,1,1,1,1,1,1,1
1,1,1,1,2,2,2,1,1,1,1,1,1,1
1,1,1,1,2,2,1,1,1,1,1,1,1,1
1,1,2,2,2,1,1,1,1,1,1,17,16,1
1,1,2,2,2,1,1,1,1,1,1,19,18,1
1,1,1,5,1,1,1,1,1,1,1,1,1,1
1,1,1,1,1,1,1,1,1,1,1,1,1,1
1,1,1,1,1,1,1,1,1,1,1,1,1,1
1,1,1,1,1,1,1,1,1,1,1,1,1,1
1,1,1,1,1,1,1,1,1,1,1,1,1,1
1,1,1,1,1,1,1,1,1,1,1,1,1,1
1,1,1,1,1,1,1,1,1,1,1,1,1,1
endlayer

layer
1,1,1,1,1,1,1,1,1,1,1,1,1,1
1,1,1,1,1,1,1,1,1,1,1,1,1,1
1,1,1,1,2,2,2,1,1,1,1,1,1,1
1,1,1,1,2,2,2,1,1,1,1,1,1,1
1,1,1,6,2,2,8,1,1,1,1,1,1,1
1,1,2,2,2,1,1,1,1,1,1,21,20,1
1,3,2,2,2,8,1,1,1,1,1,23,22,1
1,1,1,2,5,1,1,1,1,1,1,1,1,1
1,1,1,1,1,1,1,1,1,1,1,1,1,1
1,1,1,1,1,1,1,1,1,1,1,1,1,1
1,1,1,1,1,1,1,1,1,1,1,1,1,1
1,1,1,1,1,1,1,1,1,1,1,1,1,1
1,1,1,1,1,1,1,1,1,1,1,1,1,1
1,1,1,1,1,1,1,1,1,1,1,1,1,1
endlayer

layer
1,1,1,1,1,1,1,1,1,1,1,1,1,1
1,1,1,1,1,1,1,1,1,1,1,1,1,1
1,1,1,1,2,2,2,1,1,1,1,1,1,1
1,1,1,1,2,2,2,8,1,1,1,1,1,1
1,1,3,2,2,2,2,1,1,1,1,1,1,1
1,1,2,2,2,2,8,1,1,1,1,17,16,1
1,2,2,2,2,2,1,1,1,1,1,19,18,1
1,1,5,2,2,1,1,1,1,1,1,1,1,1
1,1,1,1,1,1,1,1,1,1,1,1,1,1
1,1,1,1,1,1,1,1,1,1,1,1,1,1
1,1,1,1,1,1,1,1,1,1,1,1,1,1
1,1,1,1,1,1,1,1,1,1,1,1,1,1
1,1,1,1,1,1,1,1,1,1,1,1,1,1
1,1,1,1,1,1,1,1,1,1,1,1,1,1
endlayer

layer
1,1,1,1,1,1,1,1,1,1,1,1,1,1
1,1,1,1,1,1,1,1,1,1,1,1,1,1
1,1,1,1,2,2,2,8,1,1,1,1,1,1
1,1,1,3,2,2,2,2,1,1,1,1,1,1
1,1,2,2,2,2,2,8,1,1,1,1,1,1
1,3,2,2,2,2,2,1,1,1,1,21,20,1
1,2,2,2,2,2,1,1,1,1,1,23,22,1
1,1,2,2,2,3,1,1,1,1,1,1,1,1
1,1,1,1,1,1,1,1,1,1,1,1,1,1
1,1,1,1,1,1,1,1,1,1,1,1,1,1
1,1,1,1,1,1,1,1,1,1,1,1,1,1
1,1,1,1,1,1,1,1,1,1,1,1,1,1
1,1,1,1,1,1,1,1,1,1,1,1,1,1
1,1,1,1,1,1,1,1,1,1,1,1,1,1
endlayer

layer
1,1,1,1,1,1,1,1,1,1,1,1,1,1
1,1,1,1,1,6,1,1,1,1,1,1,1,1
1,1,1,1,2,2,2,2,1,1,1,1,1,1
1,1,1,2,2,2,2,2,1,1,1,1,1,1
1,1,2,2,2,2,2,2,1,1,1,1,1,1
1,2,2,2,2,2,2,1,1,1,1,17,16,1
1,1,2,2,2,2,6,1,1,1,1,19,18,1
1,1,2,2,2,2,1,1,1,1,1,1,1,1
1,1,1,6,1,1,1,1,1,1,1,1,1,1
1,1,1,1,1,1,1,1,1,1,1,1,1,1
1,1,1,1,1,1,1,1,1,1,1,1,1,1
1,1,1,1,1,1,1,1,1,1,1,1,1,1
1,1,1,1,1,1,1,1,1,1,1,1,1,1
1,1,1,1,1,1,1,1,1,1,1,1,1,1
endlayer

layer
1,1,1,1,1,1,1,1,1,1,1,1,1,1
1,1,1,1,1,2,1,1,1,1,1,1,1,1
1,1,1,2,2,2,2,2,1,1,1,1,1,1
1,1,2,2,2,2,2,2,3,1,1,1,1,1
1,8,2,2,2,2,2,2,1,1,1,1,1,1
1,2,2,2,2,2,2,3,1,1,1,21,20,1
1,2,2,2,2,2,2,1,1,1,1,23,22,1
1,1,2,2,2,2,1,1,1,1,1,1,1,1
1,1,1,2,6,1,1,1,1,1,1,1,1,1
1,1,1,1,1,1,1,1,1,1,1,1,1,1
1,1,1,1,1,1,1,1,1,1,1,1,1,1
1,1,1,1,1,1,1,1,1,1,1,1,1,1
1,1,1,1,1,1,1,1,1,1,1,1,1,1
1,1,1,1,1,1,1,1,1,1,1,1,1,1
endlayer

layer
1,1,1,1,1,1,1,1,1,1,1,1,1,1
1,1,1,1,1,5,2,1,1,1,1,1,1,1
1,1,1,2,2,2,2,2,3,1,1,1,1,1
1,1,8,2,2,2,2,2,2,1,1,1,1,1
1,2,2,2,2,2,2,2,3,1,1,1,1,1
1,2,2,2,2,2,2,2,1,1,1,17,16,1
1,2,2,2,2,2,2,6,1,1,1,19,18,1
1,6,2,2,2,2,1,1,1,1,1,1,1,1
1,1,2,2,2,1,1,1,1,1,1,1,1,1
1,1,1,1,1,1,1,1,1,1,1,1,1,1
1,1,1,1,1,1,1,1,1,1,1,1,1,1
1,1,1,1,1,1,1,1,1,1,1,1,1,1
1,1,1,1,1,1,1,1,1,1,1,1,1,1
1,1,1,1,1,1,1,1,1,1,1,1,1,1
endlayer

layer
1,1,1,1,1,1,1,1,1,1,1,1,1,1
1,1,1,1,1,2,2,1,1,1,1,1,1,1
1,1,1,2,2,2,2,2,2,1,1,1,1,1
1,1,2,2,2,2,2,2,2,3,1,1,1,1
1,8,2,2,2,2,2,2,2,1,1,1,1,1
1,2,2,2,2,2,2,2,1,1,1,21,20,1
1,2,2,2,2,2,2,2,1,1,1,23,22,1
1,1,2,2,2,2,3,1,1,1,1,1,1,1
1,1,2,2,2,1,1,1,1,1,1,1,1,1
1,1,1,1,1,1,1,1,1,1,1,1,1,1
1,1,1,1,1,1,1,1,1,1,1,1,1,1
1,1,1,1,1,1,1,1,1,1,1,1,1,1
1,1,1,1,1,1,1,1,1,1,1,1,1,1
1,1,1,1,1,1,1,1,1,1,1,1,1,1
endlayer

layer
1,1,1,1,1,1,1,1,1,1,1,1,1,1
1,1,1,1,2,2,2,2,1,1,1,1,1,1
1,1,5,2,2,2,2,2,2,1,1,1,1,1
1,1,2,2,2,2,2,2,2,2,1,1,1,1
1,2,2,2,2,2,2,2,2,1,1,1,1,1
1,2,2,2,2,2,2,2,2,1,1,17,16,1
1,2,2,2,2,2,2,2,1,1,1,19,18,1
1,2,2,2,2,2,2,1,1,1,1,1,1,1
1,1,2,2,2,6,1,1,1,1,1,1,1,1
1,1,1,1,1,1,1,1,1,1,1,1,1,1
1,1,1,1,1,1,1,1,1,1,1,1,1,1
1,1,1,1,1,1,1,1,1,1,1,1,1,1
1,1,1,1,1,1,1,1,1,1,1,1,1,1
1,1,1,1,1,1,1,1,1,1,1,1,1,1
endlayer

layer
1,1,1,1,1,1,1,1,1,1,1,1,1,1
1,1,1,1,1,2,2,2,1,1,1,1,1,1
1,1,4,2,2,2,2,2,2,3,1,1,1,1
1,8,2,2,2,2,2,2,2,2,1,1,1,1
1,2,2,2,2,2,2,2,2,3,1,1,1,1
8,2,2,2,2,2,2,2,2,1,1,21,20,1
1,2,2,2,2,2,2,2,1,1,1,23,22,1
1,2,2,2,2,2,2,1,1,1,1,1,1,1
1,1,2,2,2,2,1,1,1,1,1,1,1,1
1,1,1,6,1,1,1,1,1,1,1,1,1,1
1,1,1,1,1,1,1,1,1,1,1,1,1,1
1,1,1,1,1,1,1,1,1,1,1,1,1,1
1,1,1,2,3,1,1,1,1,1,1,1,1,1
1,1,1,1,1,1,1,1,1,1,1,1,1,1
endlayer

layer
1,1,1,1,1,1,5,1,1,1,1,1,1,1
1,1,1,1,2,2,2,2,5,1,1,1,1,1
1,1,2,2,2,2,2,2,2,2,1,1,1,1
1,2,2,2,2,2,2,2,2,2,1,1,1,1
1,2,2,2,2,2,2,2,2,2,1,1,1,1
2,2,2,2,2,2,2,2,2,1,1,17,16,1
8,2,2,2,2,2,2,2,1,1,1,19,18,1
1,2,2,2,2,2,2,1,1,1,1,1,1,1
1,6,2,2,2,2,1,1,1,1,1,1,1,1
1,1,6,2,1,1,1,1,1,1,1,1,1,1
1,1,1,1,1,1,1,1,1,1,1,1,1,1
1,1,1,1,1,1,1,1,1,1,1,1,1,1
1,1,1,2,2,1,1,1,1,1,1,1,1,1
1,1,1,2,3,1,1,1,1,1,1,1,1,1
endlayer

layer
1,1,1,1,1,2,2,1,1,1,1,1,1,1
1,1,1,5,2,2,2,2,2,1,1,1,1,1
1,1,2,2,2,2,2,2,2,2,1,1,1,1
1,2,2,2,2,2,2,2,2,2,1,1,1,1
1,2,2,2,2,2,2,2,2,2,1,1,1,1
2,2,2,2,2,2,2,2,2,1,1,21,20,1
2,2,2,2,2,2,2,2,1,1,1,23,22,1
1,2,2,2,2,2,2,1,1,1,1,1,1,1
1,2,2,2,2,2,1,1,1,1,1,1,1,1
1,1,2,2,6,1,1,1,1,1,1,1,1,1
1,1,1,1,1,1,1,1,1,1,1,1,1,1
1,1,1,2,1,1,1,1,1,1,1,1,1,1
1,1,2,2,2,1,1,1,1,1,1,1,1,1
1,1,8,2,2,1,1,1,1,1,1,1,1,1
endlayer

layer
1,1,1,1,5,2,2,5,1,1,1,1,1,1
1,1,1,2,2,2,2,2,2,1,1,1,1,1
1,1,2,2,2,2,2,2,2,2,1,1,1,1
1,2,2,2,2,2,2,2,2,2,1,1,1,1
8,2,2,2,2,2,2,2,2,2,1,1,1,1
2,2,2,2,2,2,2,2,2,1,1,17,16,1
2,2,2,2,2,2,2,2,1,1,1,19,18,1
1,2,2,2,2,2,2,1,1,1,1,1,1,1
1,2,2,2,2,2,1,1,1,1,1,1,1,1
1,2,2,2,2,1,1,1,1,1,1,1,1,1
1,1,1,1,1,1,1,1,1,1,1,1,1,1
1,1,1,2,1,1,1,1,1,1,1,1,1,1
1,8,2,2,1,1,1,1,1,1,1,1,1,1
1,1,7,2,9,1,1,1,1,1,1,1,1,1
endlayer

layer
1,1,1,1,2,2,2,2,1,1,1,1,1,1
1,1,1,2,2,2,2,2,2,1,1,1,1,1
1,1,2,2,2,2,2,2,2,4,1,1,1,1
1,2,2,2,2,2,2,2,2,2,1,1,1,1
2,2,2,2,2,2,2,2,2,9,1,1,1,1
2,2,2,2,2,2,2,2,2,1,1,21,20,1
2,2,2,2,2,2,2,2,1,1,1,23,22,1
8,2,2,2,2,2,7,1,1,1,1,1,1,1
1,2,2,2,2,9,1,1,1,1,1,1,1,1
1,2,2,2,7,1,1,1,1,1,1,1,1,1
1,1,1,1,1,1,1,1,1,1,1,1,1,1
1,1,2,2,1,1,1,1,1,1,1,1,1,1
1,2,2,2,1,1,1,1,1,1,1,1,1,1
1,1,1,7,1,1,1,1,1,1,1,1,1,1
endlayer

layer
1,1,1,1,4,2,2,4,1,1,1,1,1,1
1,1,1,2,2,2,2,2,4,1,1,1,1,1
1,1,2,2,2,2,2,2,2,1,1,1,1,1
1,2,2,2,2,2,2,2,2,9,1,1,1,1
10,2,2,2,2,2,2,2,2,1,1,1,1,1
2,2,2,2,2,2,2,2,9,1,1,17,16,1
2,2,2,2,2,2,2,9,1,1,1,19,18,1
2,2,2,2,2,2,1,1,1,1,1,1,1,1
1,2,2,2,2,1,1,1,1,1,1,1,1,1
1,1,2,7,1,1,1,1,1,1,1,1,1,1
1,1,1,1,1,1,1,1,1,1,1,1,1,1
1,2,2,1,1,1,1,1,1,1,1,1,1,1
1,2,2,2,1,1,1,1,1,1,1,1,1,1
1,1,1,1,1,1,1,1,1,1,1,1,1,1
endlayer

layer
1,1,1,1,1,4,4,1,1,1,1,1,1,1
1,1,1,1,2,2,2,2,1,1,1,1,1,1
1,1,1,2,2,2,2,2,4,1,1,1,1,1
1,1,2,2,2,2,2,2,2,1,1,1,1,1
1,2,2,2,2,2,2,2,9,1,1,1,1,1
10,2,2,2,2,2,2,9,1,1,1,21,20,1
2,2,2,2,2,2,9,1,1,1,1,23,22,1
1,2,2,2,2,7,1,1,1,1,1,1,1,1
1,2,2,2,7,1,1,1,1,1,1,1,1,1
1,1,1,1,1,1,1,1,1,1,1,1,1,1
1,5,2,1,1,1,1,1,1,1,1,1,1,1
8,2,2,1,1,1,1,1,1,1,1,1,1,1
1,7,2,9,1,1,1,1,1,1,1,1,1,1
1,1,1,1,1,1,1,1,1,1,1,1,1,1
endlayer

layer
1,1,1,1,1,1,1,1,1,5,3,1,1,1
1,1,1,1,4,2,2,9,1,8,2,1,1,1
1,1,1,10,2,2,2,2,1,1,1,1,1,1
1,1,4,2,2,2,2,2,1,1,1,1,1,1
1,10,2,2,2,2,2,7,1,1,1,1,1,1
1,2,2,2,2,2,2,1,1,1,1,17,16,1
1,2,2,2,2,2,1,1,1,1,1,19,18,1
1,2,2,2,2,1,1,1,1,1,1,1,1,1
1,1,2,7,1,1,1,1,1,1,1,1,1,1
1,1,1,1,1,1,1,1,1,1,1,1,1,1
1,2,2,1,1,1,1,1,1,1,1,1,1,1
2,2,2,1,1,1,1,1,1,1,1,1,1,1
1,1,7,1,1,1,1,1,1,1,1,1,1,1
1,1,1,1,1,1,1,1,1,1,1,1,1,1
endlayer

layer
1,1,1,1,1,1,1,1,1,2,2,1,1,1
1,1,1,1,1,1,1,1,1,2,2,3,1,1
1,1,1,1,4,2,2,4,1,1,8,2,1,1
1,1,1,1,2,2,2,2,1,1,1,1,1,1
1,1,4,2,2,2,2,1,1,1,1,1,1,1
1,10,2,2,2,2,2,1,1,1,1,21,20,1
1,2,2,2,2,2,1,1,1,1,1,23,22,1
1,1,2,2,2,1,1,1,1,1,1,1,1,1
1,1,1,1,1,1,1,1,1,1,1,1,1,1
1,5,1,1,1,1,1,1,1,1,1,1,1,1
8,2,2,1,1,1,1,1,1,1,1,1,1,1
2,2,2,1,1,1,1,1,1,1,1,1,1,1
1,1,1,1,1,1,1,1,1,1,1,1,1,1
1,1,1,1,1,1,1,1,1,1,1,1,1,1
endlayer

layer
1,1,1,1,1,1,1,1,1,2,2,1,1,1
1,1,1,1,1,1,1,1,8,2,2,4,1,1
1,1,1,1,1,1,1,1,1,1,2,2,3,1
1,1,1,1,4,2,2,2,1,1,1,2,6,1
1,1,1,10,2,2,2,3,1,1,1,1,1,1
1,1,2,2,2,2,2,1,1,1,1,17,16,1
1,1,2,2,2,2,1,1,1,1,1,19,18,1
1,1,1,2,2,1,1,1,1,1,1,1,1,1
1,1,1,1,1,1,1,1,1,1,1,1,1,1
1,2,1,1,1,1,1,1,1,1,1,1,1,1
2,2,9,1,1,1,1,1,1,1,1,1,1,1
10,2,1,1,1,1,1,1,1,1,1,1,1,1
1,1,1,1,1,1,1,1,1,1,1,1,1,1
1,1,1,1,1,1,1,1,1,1,1,1,1,1
endlayer

layer
1,1,1,1,1,1,1,1,1,2,2,1,1,1
1,1,1,1,1,1,1,1,2,2,2,1,1,1
1,1,1,1,1,1,1,1,1,1,1,10,9,1
1,1,1,1,1,2,2,2,1,1,1,2,2,1
1,1,1,1,2,2,2,2,1,1,1,8,3,1
1,1,1,2,2,2,2,1,1,1,1,21,20,1
1,1,2,2,2,2,3,1,1,1,1,23,22,1
1,1,1,2,2,6,1,1,1,1,1,1,1,1
1,1,1,1,1,1,1,1,1,1,1,1,1,1
8,2,1,1,1,1,1,1,1,1,1,1,1,1
2,2,1,1,1,1,1,1,1,1,1,1,1,1
1,7,1,1,1,1,1,1,1,1,1,1,1,1
1,1,1,1,1,1,1,1,1,1,1,1,1,1
1,1,1,1,1,1,1,1,1,1,1,1,1,1
endlayer

layer
1,1,1,1,1,1,1,1,5,2,2,1,1,1
1,1,1,1,1,1,1,1,2,2,9,1,1,1
1,1,1,1,1,4,1,1,1,1,1,1,1,1
1,1,1,1,1,2,2,2,1,1,1,1,4,1
1,1,1,1,2,2,2,2,1,1,1,10,2,3
1,1,1,2,2,2,2,3,1,1,1,17,14,6
1,1,2,2,2,2,2,1,1,1,1,19,18,1
1,1,1,2,2,2,1,1,1,1,1,1,1,1
1,5,1,1,1,1,1,1,1,1,1,1,1,1
2,2,1,1,1,1,1,1,1,1,1,1,1,1
2,2,1,1,1,1,1,1,1,1,1,1,1,1
1,1,1,1,1,1,1,1,1,1,1,1,1,1
1,1,1,1,1,1,1,1,1,1,1,1,1,1
1,1,1,1,1,1,1,1,1,1,1,1,1,1
endlayer

layer
1,1,1,1,1,1,1,1,2,2,2,1,1,1
1,1,1,1,1,1,1,1,2,2,1,1,1,1
1,1,1,1,1,1,4,1,1,1,1,1,1,1
1,1,1,1,2,2,2,2,1,1,1,1,1,1
1,1,1,2,2,2,2,2,1,1,1,1,4,9
1,1,2,2,2,2,2,2,1,1,1,21,14,2
1,1,2,2,2,2,2,6,1,1,1,23,22,3
1,1,1,2,2,2,3,1,1,1,1,1,1,1
8,2,1,1,1,1,1,1,1,1,1,1,1,1
2,2,1,1,1,1,1,1,1,1,1,1,1,1
2,2,1,1,1,1,1,1,1,1,1,1,1,1
1,1,1,1,1,1,1,1,1,1,1,1,1,1
1,1,1,1,1,1,1,1,1,1,1,1,1,1
1,1,1,1,1,1,1,1,1,1,1,1,1,1
endlayer

layer
1,1,1,1,1,1,1,1,2,2,9,1,1,1
1,1,1,1,1,1,4,1,2,2,1,1,1,1
1,1,1,1,1,2,2,2,1,2,1,1,1,1
1,1,1,10,2,2,2,2,5,1,1,1,1,1
1,1,5,2,2,2,2,2,2,3,1,1,1,1
1,1,2,2,2,2,2,2,2,3,1,17,16,9
1,1,2,2,2,2,2,2,6,1,1,19,18,2
1,2,2,2,2,2,2,1,1,1,1,8,6,1
2,2,1,8,2,2,3,1,1,1,1,1,1,1
2,2,1,1,6,6,1,1,1,1,1,1,1,1
2,9,1,1,1,1,1,1,1,1,1,1,1,1
1,1,1,1,1,1,1,1,1,1,1,1,1,1
1,1,1,1,1,1,1,1,1,1,1,1,1,1
1,1,1,1,1,1,1,1,1,1,1,1,1,1
endlayer

layer
1,1,1,1,1,1,1,8,2,2,1,1,1,1
1,1,1,1,1,10,2,1,2,2,1,1,1,1
1,1,1,1,2,2,2,2,2,2,1,1,1,1
1,1,1,1,2,2,2,2,2,1,1,1,1,1
1,1,1,2,2,2,2,2,2,2,1,1,1,1
1,8,2,2,2,2,2,2,2,2,1,21,20,1
1,1,2,2,2,2,2,2,2,1,1,23,22,9
1,2,2,2,2,2,2,1,1,1,1,7,7,1
2,2,1,2,2,2,2,1,1,1,1,1,1,1
2,2,1,1,2,2,1,1,1,1,1,1,1,1
7,1,1,1,1,1,1,1,1,1,1,1,1,1
1,1,1,1,1,1,1,1,1,1,1,1,1,1
1,1,1,1,1,1,1,1,1,1,1,1,1,1
1,1,1,1,1,1,1,1,1,1,1,1,1,1
endlayer

layer
1,1,1,1,1,1,1,2,2,4,1,1,1,1
1,1,1,1,1,1,2,2,2,2,1,1,1,1
1,1,1,1,2,2,2,2,2,2,1,1,1,1
1,1,1,2,2,2,2,2,2,1,1,1,1,1
1,1,2,2,2,2,2,2,2,4,1,1,1,1
1,5,2,2,2,2,2,2,2,9,1,17,16,1
1,10,2,2,2,2,2,2,7,1,1,19,18,1
8,2,2,2,2,2,2,1,1,1,1,1,1,1
2,2,2,2,2,2,9,1,1,1,1,1,1,1
2,2,3,1,10,7,1,1,1,1,1,1,1,1
1,1,1,1,1,1,1,1,1,1,1,1,1,1
1,1,1,1,1,1,1,1,1,1,1,1,1,1
1,1,1,1,1,1,1,1,1,1,1,1,1,1
1,1,1,1,1,1,1,1,1,1,1,1,1,1
endlayer

layer
1,1,1,1,1,1,8,2,2,1,1,1,1,1
1,1,1,1,1,2,2,2,2,2,1,1,1,1
1,1,1,5,2,2,2,2,2,2,1,1,1,1
1,1,4,2,2,2,2,2,2,1,1,1,1,1
1,1,2,2,2,2,2,2,2,1,1,1,1,1
1,1,2,2,2,2,2,2,9,1,1,21,20,1
1,2,2,2,2,2,2,7,1,1,1,23,22,1
2,2,2,2,2,2,9,1,1,1,1,1,1,1
2,2,2,2,2,7,1,1,1,1,1,1,1,1
7,2,2,1,1,1,1,1,1,1,1,1,1,1
1,1,1,1,1,1,1,1,1,1,1,1,1,1
1,1,1,1,1,1,1,1,1,1,1,1,1,1
1,1,1,1,1,1,1,1,1,1,1,1,1,1
1,1,1,1,1,1,1,1,1,1,1,1,1,1
endlayer

layer
1,1,1,1,1,1,2,2,4,1,1,1,1,1
1,1,1,1,10,2,2,2,2,9,1,1,1,1
1,1,1,2,2,2,2,2,2,1,1,1,1,1
1,1,2,2,2,2,2,2,2,1,1,1,1,1
1,1,2,2,2,2,2,2,9,1,1,1,1,1
1,2,2,2,2,2,2,7,1,1,1,17,16,1
1,2,2,2,2,2,7,1,1,1,1,19,18,1
10,2,2,2,2,9,1,1,1,1,1,1,1,1
2,2,2,2,7,1,1,1,1,1,1,1,1,1
1,2,7,1,1,1,1,1,1,1,1,1,1,1
1,1,1,1,1,1,1,1,1,1,1,1,1,1
1,1,1,1,1,1,1,1,1,1,1,1,1,1
1,1,1,1,1,1,1,1,1,1,1,1,1,1
1,1,1,1,1,1,1,1,1,1,1,1,1,1
endlayer

layer
1,1,1,1,1,1,10,4,1,1,1,1,1,1
1,1,1,1,1,2,2,2,2,1,1,1,1,1
1,1,8,2,2,2,2,2,2,1,1,1,1,1
1,1,2,2,2,2,2,2,9,1,1,1,1,1
1,4,2,2,2,2,2,9,1,1,1,1,1,1
1,2,2,2,2,2,7,1,1,1,1,21,20,1
1,2,2,2,2,9,1,1,1,1,1,23,22,1
1,2,2,2,7,1,1,1,1,1,1,1,1,1
1,10,2,9,1,1,1,1,1,1,1,1,1,1
1,1,1,1,1,1,1,1,1,1,1,1,1,1
1,1,1,1,1,1,1,1,1,1,1,1,1,1
1,1,1,1,1,1,1,1,1,1,1,1,1,1
1,1,1,1,1,1,1,1,1,1,1,1,1,1
1,1,1,1,1,1,1,1,1,1,1,1,1,1
endlayer

layer
1,1,1,1,1,1,1,1,1,1,1,1,1,1
1,1,1,1,10,2,2,2,1,1,1,1,1,1
1,1,1,2,2,2,2,2,1,1,1,1,1,1
1,1,2,2,2,2,2,9,1,1,1,1,1,1
1,1,2,2,2,2,7,1,1,1,1,1,1,1
1,2,2,2,2,2,1,1,1,1,1,17,16,1
1,2,2,2,9,1,1,1,1,1,1,19,18,1
1,2,2,7,1,1,1,1,1,1,1,1,1,1
1,1,7,1,1,1,1,1,1,1,1,1,1,1
1,1,1,1,1,1,1,1,1,1,1,1,1,1
1,1,1,1,1,1,1,1,1,1,1,1,1,1
1,1,1,1,1,1,1,1,1,1,1,1,1,1
1,1,1,1,1,1,1,1,1,1,1,1,1,1
1,1,1,1,1,1,1,1,1,1,1,1,1,1
endlayer

layer
1,1,1,1,1,1,1,1,1,1,1,1,1,1
1,1,1,1,2,2,1,1,1,1,1,1,1,1
1,1,10,2,2,2,2,9,1,1,1,1,1,1
1,1,2,2,2,2,2,1,1,1,1,1,1,1
1,5,2,2,2,2,1,1,1,1,1,1,1,1
1,2,2,2,2,2,1,1,1,1,1,21,20,1
1,2,2,2,1,1,1,1,1,1,1,23,22,1
1,1,6,1,1,1,1,1,1,1,1,1,1,1
1,1,1,1,1,1,1,1,1,1,1,1,1,1
1,1,1,1,1,1,1,1,1,1,1,1,1,1
1,1,1,1,1,1,1,1,1,1,1,1,1,1
1,1,1,1,1,1,1,1,1,1,1,1,1,1
1,1,1,1,1,1,1,1,1,1,1,1,1,1
1,1,1,1,1,1,1,1,1,1,1,1,1,1
endlayer

layer
1,1,1,1,1,1,1,1,1,1,1,1,1,1
1,1,1,10,2,2,9,1,1,1,1,1,1,1
1,1,1,2,2,2,2,2,1,1,1,1,1,1
1,1,1,2,2,2,2,1,1,1,1,1,1,1
1,1,2,2,2,2,13,1,1,1,1,1,1,1
1,2,2,2,2,2,13,1,1,1,1,17,16,1
1,2,2,2,13,13,1,1,1,1,1,19,18,1
1,6,2,1,1,1,1,1,1,1,1,1,1,1
1,1,1,1,1,1,1,1,1,1,1,1,1,1
1,1,1,1,1,1,1,1,1,1,1,1,1,1
1,1,1,1,1,1,1,1,1,1,1,1,1,1
1,1,1,1,1,1,1,1,1,1,1,1,1,1
1,1,1,1,1,1,1,1,1,1,1,1,1,1
1,1,1,1,1,1,1,1,1,1,1,1,1,1
endlayer

layer
1,1,1,1,1,1,1,1,1,1,1,1,1,1
1,1,1,1,1,2,2,1,1,1,1,1,1,1
1,1,10,2,2,2,2,9,1,1,1,1,1,1
1,1,8,2,2,2,2,1,1,1,1,1,1,1
1,1,2,2,2,2,2,3,1,1,1,1,1,1
1,2,2,2,2,2,2,5,1,1,1,21,20,1
1,1,2,2,2,2,2,2,1,1,1,23,22,1
1,1,7,1,6,8,2,1,1,1,1,1,1,1
1,1,1,1,1,1,1,1,1,1,1,1,1,1
1,1,1,1,1,1,1,1,1,1,1,1,1,1
1,1,1,1,1,1,1,1,1,1,1,1,1,1
1,1,1,1,1,1,1,1,1,1,1,1,1,1
1,1,1,1,1,1,1,1,1,1,1,1,1,1
1,1,1,1,1,1,1,1,1,1,1,1,1,1
endlayer

layer
1,1,1,1,1,1,1,1,1,1,1,1,1,1
1,1,1,1,10,2,1,1,1,1,1,1,1,1
1,1,1,2,2,2,2,1,1,1,1,1,1,1
1,1,10,2,2,2,2,2,1,1,1,1,1,1
1,5,2,2,2,2,2,2,1,1,1,1,1,1
1,2,2,2,2,2,2,2,1,1,1,17,16,1
1,2,2,2,2,2,2,2,1,1,1,19,18,1
1,1,2,1,2,2,2,1,1,1,1,1,1,1
1,1,1,1,1,1,1,1,1,1,1,1,1,1
1,1,1,1,1,1,1,1,1,1,1,1,1,1
1,1,1,1,1,1,1,1,1,1,1,1,1,1
1,1,1,1,1,1,1,1,1,1,1,1,1,1
1,1,1,1,1,1,1,1,1,1,1,1,1,1
1,1,1,1,1,1,1,1,1,1,1,1,1,1
endlayer

layer
1,1,1,1,1,1,1,1,1,1,1,1,1,1
1,1,1,1,1,3,1,1,1,1,1,1,1,1
1,1,1,1,2,2,2,2,1,1,1,1,1,1
1,1,2,2,2,2,2,2,1,1,1,1,1,1
1,1,2,2,2,2,2,2,1,1,1,1,1,1
1,2,2,2,2,2,2,2,1,1,1,21,20,1
1,1,2,2,2,2,2,2,1,1,1,23,22,1
1,1,1,2,2,2,2,1,1,1,1,1,1,1
1,1,1,1,1,1,1,1,1,1,1,1,1,1
1,1,1,1,1,1,1,1,1,1,1,1,1,1
1,1,1,1,1,1,1,1,1,1,1,1,1,1
1,1,1,1,1,1,1,1,1,1,1,1,1,1
1,1,1,1,1,1,1,1,1,1,1,1,1,1
1,1,1,1,1,1,1,1,1,1,1,1,1,1
endlayer

layer
1,1,1,1,1,1,1,1,1,1,1,1,1,1
1,1,1,1,1,1,1,1,1,1,1,1,1,1
1,1,1,2,2,2,2,9,1,1,1,1,1,1
1,1,1,2,2,2,2,2,1,1,1,1,1,1
1,1,2,2,2,2,2,2,1,1,1,1,1,1
1,1,2,2,2,2,2,2,1,1,1,17,16,1
1,1,2,2,2,2,2,1,1,1,1,19,18,1
1,1,1,7,2,2,2,1,1,1,1,1,1,1
1,1,1,1,1,1,1,1,1,1,1,1,1,1
1,1,1,1,1,1,1,1,1,1,1,1,1,1
1,1,1,1,1,1,1,1,1,1,1,1,1,1
1,1,1,1,1,1,1,1,1,1,1,1,1,1
1,1,1,1,1,1,1,1,1,1,1,1,1,1
1,1,1,1,1,1,1,1,1,1,1,1,1,1
endlayer

layer
1,1,1,1,1,1,1,1,1,1,1,1,1,1
1,1,1,1,1,1,1,1,1,1,1,1,1,1
1,1,1,1,2,2,1,1,1,1,1,1,1,1
1,1,1,2,2,2,2,2,1,1,1,1,1,1
1,1,2,2,2,2,2,2,1,1,1,1,1,1
1,1,2,2,2,2,2,2,1,1,1,21,20,1
1,1,1,2,2,2,2,1,1,1,1,23,22,1
1,1,1,1,2,2,2,1,1,1,1,1,1,1
1,1,1,1,1,1,1,1,1,1,1,1,1,1
1,1,1,1,1,1,1,1,1,1,1,1,1,1
1,1,1,1,1,1,1,1,1,1,1,1,1,1
1,1,1,1,1,1,1,1,1,1,1,1,1,1
1,1,1,1,1,1,1,1,1,1,1,1,1,1
1,1,1,1,1,1,1,1,1,1,1,1,1,1
endlayer

layer
1,1,1,1,1,1,1,1,1,1,1,1,1,1
1,1,1,1,1,1,1,1,1,1,1,1,1,1
1,1,1,1,1,1,1,1,1,1,1,1,1,1
1,1,1,1,2,2,2,9,1,1,1,1,1,1
1,1,1,2,2,2,2,2,1,1,1,1,1,1
1,1,1,2,2,2,2,1,1,1,1,17,16,1
1,1,1,10,2,2,2,1,1,1,1,19,18,1
1,1,1,1,7,2,1,1,1,1,1,1,1,1
1,1,1,1,1,1,1,1,1,1,1,1,1,1
1,1,1,1,1,1,1,1,1,1,1,1,1,1
1,1,1,1,1,1,1,1,1,1,1,1,1,1
1,1,1,1,1,1,1,1,1,1,1,1,1,1
1,1,1,1,1,1,1,1,1,1,1,1,1,1
1,1,1,1,1,1,1,1,1,1,1,1,1,1
endlayer

layer
1,1,1,1,1,1,1,1,1,1,1,1,1,1
1,1,1,1,1,1,1,1,1,1,1,1,1,1
1,1,1,1,1,1,1,1,1,1,1,1,1,1
1,1,1,1,1,1,1,1,1,1,1,1,1,1
1,1,1,1,1,1,1,1,1,1,1,1,1,1
1,1,1,1,1,1,1,1,1,1,1,21,20,1
1,1,1,1,1,1,1,1,1,1,1,23,22,1
1,1,1,1,1,1,1,1,1,1,1,1,1,1
1,1,1,1,1,1,1,1,1,1,1,1,1,1
1,1,1,1,1,1,1,1,1,1,1,1,1,1
1,1,1,1,1,1,1,1,1,1,1,1,1,1
1,1,1,1,1,1,1,1,1,1,1,1,1,1
1,1,1,1,1,1,1,1,1,1,1,1,1,1
1,1,1,1,1,1,1,1,1,1,1,1,1,1
endlayer

layer
1,1,1,1,1,1,1,1,1,1,1,1,1,1
1,1,1,1,1,1,1,1,1,1,1,1,1,1
1,1,1,1,1,1,1,1,1,1,1,1,1,1
1,1,1,1,1,1,1,1,1,1,1,1,1,1
1,1,1,1,1,1,1,1,1,1,1,1,1,1
1,1,1,1,1,1,1,1,1,1,1,14,14,1
1,1,1,1,1,1,1,1,1,1,1,14,14,1
1,1,1,1,1,1,1,1,1,1,1,1,1,1
1,1,1,1,1,1,1,1,1,1,1,1,1,1
1,1,1,1,1,1,1,1,1,1,1,1,1,1
1,1,1,1,1,1,1,1,1,1,1,1,1,1
1,1,1,1,1,1,1,1,1,1,1,1,1,1
1,1,1,1,1,1,1,1,1,1,1,1,1,1
1,1,1,1,1,1,1,1,1,1,1,1,1,1
endlayer

